2023-10-10 21:27:58,824 django.request ERROR    Internal Server Error: /
Traceback (most recent call last):
  File "/home/kayprogrammer/Documents/Projects/Django/socialnet-v2/env/lib/python3.11/site-packages/django/template/base.py", line 880, in _resolve_lookup
    current = current[bit]
              ~~~~~~~^^^^^
TypeError: 'TemplatesPanel' object is not subscriptable

During handling of the above exception, another exception occurred:

Traceback (most recent call last):
  File "/home/kayprogrammer/Documents/Projects/Django/socialnet-v2/env/lib/python3.11/site-packages/django/urls/base.py", line 71, in reverse
    extra, resolver = resolver.namespace_dict[ns]
                      ~~~~~~~~~~~~~~~~~~~~~~~^^^^
KeyError: 'djdt'

During handling of the above exception, another exception occurred:

Traceback (most recent call last):
  File "/home/kayprogrammer/Documents/Projects/Django/socialnet-v2/env/lib/python3.11/site-packages/django/core/handlers/exception.py", line 55, in inner
    response = get_response(request)
               ^^^^^^^^^^^^^^^^^^^^^
  File "/home/kayprogrammer/Documents/Projects/Django/socialnet-v2/env/lib/python3.11/site-packages/debug_toolbar/middleware.py", line 74, in __call__
    rendered = toolbar.render_toolbar()
               ^^^^^^^^^^^^^^^^^^^^^^^^
  File "/home/kayprogrammer/Documents/Projects/Django/socialnet-v2/env/lib/python3.11/site-packages/debug_toolbar/toolbar.py", line 82, in render_toolbar
    return render_to_string("debug_toolbar/base.html", context)
           ^^^^^^^^^^^^^^^^^^^^^^^^^^^^^^^^^^^^^^^^^^^^^^^^^^^^
  File "/home/kayprogrammer/Documents/Projects/Django/socialnet-v2/env/lib/python3.11/site-packages/django/template/loader.py", line 62, in render_to_string
    return template.render(context, request)
           ^^^^^^^^^^^^^^^^^^^^^^^^^^^^^^^^^
  File "/home/kayprogrammer/Documents/Projects/Django/socialnet-v2/env/lib/python3.11/site-packages/django/template/backends/django.py", line 61, in render
    return self.template.render(context)
           ^^^^^^^^^^^^^^^^^^^^^^^^^^^^^
  File "/home/kayprogrammer/Documents/Projects/Django/socialnet-v2/env/lib/python3.11/site-packages/django/template/base.py", line 175, in render
    return self._render(context)
           ^^^^^^^^^^^^^^^^^^^^^
  File "/home/kayprogrammer/Documents/Projects/Django/socialnet-v2/env/lib/python3.11/site-packages/django/test/utils.py", line 112, in instrumented_test_render
    return self.nodelist.render(context)
           ^^^^^^^^^^^^^^^^^^^^^^^^^^^^^
  File "/home/kayprogrammer/Documents/Projects/Django/socialnet-v2/env/lib/python3.11/site-packages/django/template/base.py", line 1005, in render
    return SafeString("".join([node.render_annotated(context) for node in self]))
                              ^^^^^^^^^^^^^^^^^^^^^^^^^^^^^^^^^^^^^^^^^^^^^^^^^
  File "/home/kayprogrammer/Documents/Projects/Django/socialnet-v2/env/lib/python3.11/site-packages/django/template/base.py", line 1005, in <listcomp>
    return SafeString("".join([node.render_annotated(context) for node in self]))
                               ^^^^^^^^^^^^^^^^^^^^^^^^^^^^^^
  File "/home/kayprogrammer/Documents/Projects/Django/socialnet-v2/env/lib/python3.11/site-packages/django/template/base.py", line 966, in render_annotated
    return self.render(context)
           ^^^^^^^^^^^^^^^^^^^^
  File "/home/kayprogrammer/Documents/Projects/Django/socialnet-v2/env/lib/python3.11/site-packages/django/template/defaulttags.py", line 238, in render
    nodelist.append(node.render_annotated(context))
                    ^^^^^^^^^^^^^^^^^^^^^^^^^^^^^^
  File "/home/kayprogrammer/Documents/Projects/Django/socialnet-v2/env/lib/python3.11/site-packages/django/template/base.py", line 966, in render_annotated
    return self.render(context)
           ^^^^^^^^^^^^^^^^^^^^
  File "/home/kayprogrammer/Documents/Projects/Django/socialnet-v2/env/lib/python3.11/site-packages/django/template/loader_tags.py", line 208, in render
    return template.render(context)
           ^^^^^^^^^^^^^^^^^^^^^^^^
  File "/home/kayprogrammer/Documents/Projects/Django/socialnet-v2/env/lib/python3.11/site-packages/django/template/base.py", line 177, in render
    return self._render(context)
           ^^^^^^^^^^^^^^^^^^^^^
  File "/home/kayprogrammer/Documents/Projects/Django/socialnet-v2/env/lib/python3.11/site-packages/django/test/utils.py", line 112, in instrumented_test_render
    return self.nodelist.render(context)
           ^^^^^^^^^^^^^^^^^^^^^^^^^^^^^
  File "/home/kayprogrammer/Documents/Projects/Django/socialnet-v2/env/lib/python3.11/site-packages/django/template/base.py", line 1005, in render
    return SafeString("".join([node.render_annotated(context) for node in self]))
                              ^^^^^^^^^^^^^^^^^^^^^^^^^^^^^^^^^^^^^^^^^^^^^^^^^
  File "/home/kayprogrammer/Documents/Projects/Django/socialnet-v2/env/lib/python3.11/site-packages/django/template/base.py", line 1005, in <listcomp>
    return SafeString("".join([node.render_annotated(context) for node in self]))
                               ^^^^^^^^^^^^^^^^^^^^^^^^^^^^^^
  File "/home/kayprogrammer/Documents/Projects/Django/socialnet-v2/env/lib/python3.11/site-packages/django/template/base.py", line 966, in render_annotated
    return self.render(context)
           ^^^^^^^^^^^^^^^^^^^^
  File "/home/kayprogrammer/Documents/Projects/Django/socialnet-v2/env/lib/python3.11/site-packages/django/template/defaulttags.py", line 321, in render
    return nodelist.render(context)
           ^^^^^^^^^^^^^^^^^^^^^^^^
  File "/home/kayprogrammer/Documents/Projects/Django/socialnet-v2/env/lib/python3.11/site-packages/django/template/base.py", line 1005, in render
    return SafeString("".join([node.render_annotated(context) for node in self]))
                              ^^^^^^^^^^^^^^^^^^^^^^^^^^^^^^^^^^^^^^^^^^^^^^^^^
  File "/home/kayprogrammer/Documents/Projects/Django/socialnet-v2/env/lib/python3.11/site-packages/django/template/base.py", line 1005, in <listcomp>
    return SafeString("".join([node.render_annotated(context) for node in self]))
                               ^^^^^^^^^^^^^^^^^^^^^^^^^^^^^^
  File "/home/kayprogrammer/Documents/Projects/Django/socialnet-v2/env/lib/python3.11/site-packages/django/template/base.py", line 966, in render_annotated
    return self.render(context)
           ^^^^^^^^^^^^^^^^^^^^
  File "/home/kayprogrammer/Documents/Projects/Django/socialnet-v2/env/lib/python3.11/site-packages/django/template/defaulttags.py", line 321, in render
    return nodelist.render(context)
           ^^^^^^^^^^^^^^^^^^^^^^^^
  File "/home/kayprogrammer/Documents/Projects/Django/socialnet-v2/env/lib/python3.11/site-packages/django/template/base.py", line 1005, in render
    return SafeString("".join([node.render_annotated(context) for node in self]))
                              ^^^^^^^^^^^^^^^^^^^^^^^^^^^^^^^^^^^^^^^^^^^^^^^^^
  File "/home/kayprogrammer/Documents/Projects/Django/socialnet-v2/env/lib/python3.11/site-packages/django/template/base.py", line 1005, in <listcomp>
    return SafeString("".join([node.render_annotated(context) for node in self]))
                               ^^^^^^^^^^^^^^^^^^^^^^^^^^^^^^
  File "/home/kayprogrammer/Documents/Projects/Django/socialnet-v2/env/lib/python3.11/site-packages/django/template/base.py", line 966, in render_annotated
    return self.render(context)
           ^^^^^^^^^^^^^^^^^^^^
  File "/home/kayprogrammer/Documents/Projects/Django/socialnet-v2/env/lib/python3.11/site-packages/django/template/base.py", line 1064, in render
    output = self.filter_expression.resolve(context)
             ^^^^^^^^^^^^^^^^^^^^^^^^^^^^^^^^^^^^^^^
  File "/home/kayprogrammer/Documents/Projects/Django/socialnet-v2/env/lib/python3.11/site-packages/django/template/base.py", line 715, in resolve
    obj = self.var.resolve(context)
          ^^^^^^^^^^^^^^^^^^^^^^^^^
  File "/home/kayprogrammer/Documents/Projects/Django/socialnet-v2/env/lib/python3.11/site-packages/django/template/base.py", line 847, in resolve
    value = self._resolve_lookup(context)
            ^^^^^^^^^^^^^^^^^^^^^^^^^^^^^
  File "/home/kayprogrammer/Documents/Projects/Django/socialnet-v2/env/lib/python3.11/site-packages/django/template/base.py", line 890, in _resolve_lookup
    current = getattr(current, bit)
              ^^^^^^^^^^^^^^^^^^^^^
  File "/home/kayprogrammer/Documents/Projects/Django/socialnet-v2/env/lib/python3.11/site-packages/debug_toolbar/panels/__init__.py", line 103, in content
    return render_to_string(self.template, self.get_stats())
           ^^^^^^^^^^^^^^^^^^^^^^^^^^^^^^^^^^^^^^^^^^^^^^^^^
  File "/home/kayprogrammer/Documents/Projects/Django/socialnet-v2/env/lib/python3.11/site-packages/django/template/loader.py", line 62, in render_to_string
    return template.render(context, request)
           ^^^^^^^^^^^^^^^^^^^^^^^^^^^^^^^^^
  File "/home/kayprogrammer/Documents/Projects/Django/socialnet-v2/env/lib/python3.11/site-packages/django/template/backends/django.py", line 61, in render
    return self.template.render(context)
           ^^^^^^^^^^^^^^^^^^^^^^^^^^^^^
  File "/home/kayprogrammer/Documents/Projects/Django/socialnet-v2/env/lib/python3.11/site-packages/django/template/base.py", line 175, in render
    return self._render(context)
           ^^^^^^^^^^^^^^^^^^^^^
  File "/home/kayprogrammer/Documents/Projects/Django/socialnet-v2/env/lib/python3.11/site-packages/django/test/utils.py", line 112, in instrumented_test_render
    return self.nodelist.render(context)
           ^^^^^^^^^^^^^^^^^^^^^^^^^^^^^
  File "/home/kayprogrammer/Documents/Projects/Django/socialnet-v2/env/lib/python3.11/site-packages/django/template/base.py", line 1005, in render
    return SafeString("".join([node.render_annotated(context) for node in self]))
                              ^^^^^^^^^^^^^^^^^^^^^^^^^^^^^^^^^^^^^^^^^^^^^^^^^
  File "/home/kayprogrammer/Documents/Projects/Django/socialnet-v2/env/lib/python3.11/site-packages/django/template/base.py", line 1005, in <listcomp>
    return SafeString("".join([node.render_annotated(context) for node in self]))
                               ^^^^^^^^^^^^^^^^^^^^^^^^^^^^^^
  File "/home/kayprogrammer/Documents/Projects/Django/socialnet-v2/env/lib/python3.11/site-packages/django/template/base.py", line 966, in render_annotated
    return self.render(context)
           ^^^^^^^^^^^^^^^^^^^^
  File "/home/kayprogrammer/Documents/Projects/Django/socialnet-v2/env/lib/python3.11/site-packages/django/template/defaulttags.py", line 321, in render
    return nodelist.render(context)
           ^^^^^^^^^^^^^^^^^^^^^^^^
  File "/home/kayprogrammer/Documents/Projects/Django/socialnet-v2/env/lib/python3.11/site-packages/django/template/base.py", line 1005, in render
    return SafeString("".join([node.render_annotated(context) for node in self]))
                              ^^^^^^^^^^^^^^^^^^^^^^^^^^^^^^^^^^^^^^^^^^^^^^^^^
  File "/home/kayprogrammer/Documents/Projects/Django/socialnet-v2/env/lib/python3.11/site-packages/django/template/base.py", line 1005, in <listcomp>
    return SafeString("".join([node.render_annotated(context) for node in self]))
                               ^^^^^^^^^^^^^^^^^^^^^^^^^^^^^^
  File "/home/kayprogrammer/Documents/Projects/Django/socialnet-v2/env/lib/python3.11/site-packages/django/template/base.py", line 966, in render_annotated
    return self.render(context)
           ^^^^^^^^^^^^^^^^^^^^
  File "/home/kayprogrammer/Documents/Projects/Django/socialnet-v2/env/lib/python3.11/site-packages/django/template/defaulttags.py", line 238, in render
    nodelist.append(node.render_annotated(context))
                    ^^^^^^^^^^^^^^^^^^^^^^^^^^^^^^
  File "/home/kayprogrammer/Documents/Projects/Django/socialnet-v2/env/lib/python3.11/site-packages/django/template/base.py", line 966, in render_annotated
    return self.render(context)
           ^^^^^^^^^^^^^^^^^^^^
  File "/home/kayprogrammer/Documents/Projects/Django/socialnet-v2/env/lib/python3.11/site-packages/django/template/defaulttags.py", line 471, in render
    url = reverse(view_name, args=args, kwargs=kwargs, current_app=current_app)
          ^^^^^^^^^^^^^^^^^^^^^^^^^^^^^^^^^^^^^^^^^^^^^^^^^^^^^^^^^^^^^^^^^^^^^
  File "/home/kayprogrammer/Documents/Projects/Django/socialnet-v2/env/lib/python3.11/site-packages/django/urls/base.py", line 82, in reverse
    raise NoReverseMatch("%s is not a registered namespace" % key)
django.urls.exceptions.NoReverseMatch: 'djdt' is not a registered namespace
2023-10-10 21:27:59,639 django.request ERROR    Internal Server Error: /favicon.ico
Traceback (most recent call last):
  File "/home/kayprogrammer/Documents/Projects/Django/socialnet-v2/env/lib/python3.11/site-packages/django/template/base.py", line 880, in _resolve_lookup
    current = current[bit]
              ~~~~~~~^^^^^
TypeError: 'TemplatesPanel' object is not subscriptable

During handling of the above exception, another exception occurred:

Traceback (most recent call last):
  File "/home/kayprogrammer/Documents/Projects/Django/socialnet-v2/env/lib/python3.11/site-packages/django/urls/base.py", line 71, in reverse
    extra, resolver = resolver.namespace_dict[ns]
                      ~~~~~~~~~~~~~~~~~~~~~~~^^^^
KeyError: 'djdt'

During handling of the above exception, another exception occurred:

Traceback (most recent call last):
  File "/home/kayprogrammer/Documents/Projects/Django/socialnet-v2/env/lib/python3.11/site-packages/django/core/handlers/exception.py", line 55, in inner
    response = get_response(request)
               ^^^^^^^^^^^^^^^^^^^^^
  File "/home/kayprogrammer/Documents/Projects/Django/socialnet-v2/env/lib/python3.11/site-packages/debug_toolbar/middleware.py", line 74, in __call__
    rendered = toolbar.render_toolbar()
               ^^^^^^^^^^^^^^^^^^^^^^^^
  File "/home/kayprogrammer/Documents/Projects/Django/socialnet-v2/env/lib/python3.11/site-packages/debug_toolbar/toolbar.py", line 82, in render_toolbar
    return render_to_string("debug_toolbar/base.html", context)
           ^^^^^^^^^^^^^^^^^^^^^^^^^^^^^^^^^^^^^^^^^^^^^^^^^^^^
  File "/home/kayprogrammer/Documents/Projects/Django/socialnet-v2/env/lib/python3.11/site-packages/django/template/loader.py", line 62, in render_to_string
    return template.render(context, request)
           ^^^^^^^^^^^^^^^^^^^^^^^^^^^^^^^^^
  File "/home/kayprogrammer/Documents/Projects/Django/socialnet-v2/env/lib/python3.11/site-packages/django/template/backends/django.py", line 61, in render
    return self.template.render(context)
           ^^^^^^^^^^^^^^^^^^^^^^^^^^^^^
  File "/home/kayprogrammer/Documents/Projects/Django/socialnet-v2/env/lib/python3.11/site-packages/django/template/base.py", line 175, in render
    return self._render(context)
           ^^^^^^^^^^^^^^^^^^^^^
  File "/home/kayprogrammer/Documents/Projects/Django/socialnet-v2/env/lib/python3.11/site-packages/django/test/utils.py", line 112, in instrumented_test_render
    return self.nodelist.render(context)
           ^^^^^^^^^^^^^^^^^^^^^^^^^^^^^
  File "/home/kayprogrammer/Documents/Projects/Django/socialnet-v2/env/lib/python3.11/site-packages/django/template/base.py", line 1005, in render
    return SafeString("".join([node.render_annotated(context) for node in self]))
                              ^^^^^^^^^^^^^^^^^^^^^^^^^^^^^^^^^^^^^^^^^^^^^^^^^
  File "/home/kayprogrammer/Documents/Projects/Django/socialnet-v2/env/lib/python3.11/site-packages/django/template/base.py", line 1005, in <listcomp>
    return SafeString("".join([node.render_annotated(context) for node in self]))
                               ^^^^^^^^^^^^^^^^^^^^^^^^^^^^^^
  File "/home/kayprogrammer/Documents/Projects/Django/socialnet-v2/env/lib/python3.11/site-packages/django/template/base.py", line 966, in render_annotated
    return self.render(context)
           ^^^^^^^^^^^^^^^^^^^^
  File "/home/kayprogrammer/Documents/Projects/Django/socialnet-v2/env/lib/python3.11/site-packages/django/template/defaulttags.py", line 238, in render
    nodelist.append(node.render_annotated(context))
                    ^^^^^^^^^^^^^^^^^^^^^^^^^^^^^^
  File "/home/kayprogrammer/Documents/Projects/Django/socialnet-v2/env/lib/python3.11/site-packages/django/template/base.py", line 966, in render_annotated
    return self.render(context)
           ^^^^^^^^^^^^^^^^^^^^
  File "/home/kayprogrammer/Documents/Projects/Django/socialnet-v2/env/lib/python3.11/site-packages/django/template/loader_tags.py", line 208, in render
    return template.render(context)
           ^^^^^^^^^^^^^^^^^^^^^^^^
  File "/home/kayprogrammer/Documents/Projects/Django/socialnet-v2/env/lib/python3.11/site-packages/django/template/base.py", line 177, in render
    return self._render(context)
           ^^^^^^^^^^^^^^^^^^^^^
  File "/home/kayprogrammer/Documents/Projects/Django/socialnet-v2/env/lib/python3.11/site-packages/django/test/utils.py", line 112, in instrumented_test_render
    return self.nodelist.render(context)
           ^^^^^^^^^^^^^^^^^^^^^^^^^^^^^
  File "/home/kayprogrammer/Documents/Projects/Django/socialnet-v2/env/lib/python3.11/site-packages/django/template/base.py", line 1005, in render
    return SafeString("".join([node.render_annotated(context) for node in self]))
                              ^^^^^^^^^^^^^^^^^^^^^^^^^^^^^^^^^^^^^^^^^^^^^^^^^
  File "/home/kayprogrammer/Documents/Projects/Django/socialnet-v2/env/lib/python3.11/site-packages/django/template/base.py", line 1005, in <listcomp>
    return SafeString("".join([node.render_annotated(context) for node in self]))
                               ^^^^^^^^^^^^^^^^^^^^^^^^^^^^^^
  File "/home/kayprogrammer/Documents/Projects/Django/socialnet-v2/env/lib/python3.11/site-packages/django/template/base.py", line 966, in render_annotated
    return self.render(context)
           ^^^^^^^^^^^^^^^^^^^^
  File "/home/kayprogrammer/Documents/Projects/Django/socialnet-v2/env/lib/python3.11/site-packages/django/template/defaulttags.py", line 321, in render
    return nodelist.render(context)
           ^^^^^^^^^^^^^^^^^^^^^^^^
  File "/home/kayprogrammer/Documents/Projects/Django/socialnet-v2/env/lib/python3.11/site-packages/django/template/base.py", line 1005, in render
    return SafeString("".join([node.render_annotated(context) for node in self]))
                              ^^^^^^^^^^^^^^^^^^^^^^^^^^^^^^^^^^^^^^^^^^^^^^^^^
  File "/home/kayprogrammer/Documents/Projects/Django/socialnet-v2/env/lib/python3.11/site-packages/django/template/base.py", line 1005, in <listcomp>
    return SafeString("".join([node.render_annotated(context) for node in self]))
                               ^^^^^^^^^^^^^^^^^^^^^^^^^^^^^^
  File "/home/kayprogrammer/Documents/Projects/Django/socialnet-v2/env/lib/python3.11/site-packages/django/template/base.py", line 966, in render_annotated
    return self.render(context)
           ^^^^^^^^^^^^^^^^^^^^
  File "/home/kayprogrammer/Documents/Projects/Django/socialnet-v2/env/lib/python3.11/site-packages/django/template/defaulttags.py", line 321, in render
    return nodelist.render(context)
           ^^^^^^^^^^^^^^^^^^^^^^^^
  File "/home/kayprogrammer/Documents/Projects/Django/socialnet-v2/env/lib/python3.11/site-packages/django/template/base.py", line 1005, in render
    return SafeString("".join([node.render_annotated(context) for node in self]))
                              ^^^^^^^^^^^^^^^^^^^^^^^^^^^^^^^^^^^^^^^^^^^^^^^^^
  File "/home/kayprogrammer/Documents/Projects/Django/socialnet-v2/env/lib/python3.11/site-packages/django/template/base.py", line 1005, in <listcomp>
    return SafeString("".join([node.render_annotated(context) for node in self]))
                               ^^^^^^^^^^^^^^^^^^^^^^^^^^^^^^
  File "/home/kayprogrammer/Documents/Projects/Django/socialnet-v2/env/lib/python3.11/site-packages/django/template/base.py", line 966, in render_annotated
    return self.render(context)
           ^^^^^^^^^^^^^^^^^^^^
  File "/home/kayprogrammer/Documents/Projects/Django/socialnet-v2/env/lib/python3.11/site-packages/django/template/base.py", line 1064, in render
    output = self.filter_expression.resolve(context)
             ^^^^^^^^^^^^^^^^^^^^^^^^^^^^^^^^^^^^^^^
  File "/home/kayprogrammer/Documents/Projects/Django/socialnet-v2/env/lib/python3.11/site-packages/django/template/base.py", line 715, in resolve
    obj = self.var.resolve(context)
          ^^^^^^^^^^^^^^^^^^^^^^^^^
  File "/home/kayprogrammer/Documents/Projects/Django/socialnet-v2/env/lib/python3.11/site-packages/django/template/base.py", line 847, in resolve
    value = self._resolve_lookup(context)
            ^^^^^^^^^^^^^^^^^^^^^^^^^^^^^
  File "/home/kayprogrammer/Documents/Projects/Django/socialnet-v2/env/lib/python3.11/site-packages/django/template/base.py", line 890, in _resolve_lookup
    current = getattr(current, bit)
              ^^^^^^^^^^^^^^^^^^^^^
  File "/home/kayprogrammer/Documents/Projects/Django/socialnet-v2/env/lib/python3.11/site-packages/debug_toolbar/panels/__init__.py", line 103, in content
    return render_to_string(self.template, self.get_stats())
           ^^^^^^^^^^^^^^^^^^^^^^^^^^^^^^^^^^^^^^^^^^^^^^^^^
  File "/home/kayprogrammer/Documents/Projects/Django/socialnet-v2/env/lib/python3.11/site-packages/django/template/loader.py", line 62, in render_to_string
    return template.render(context, request)
           ^^^^^^^^^^^^^^^^^^^^^^^^^^^^^^^^^
  File "/home/kayprogrammer/Documents/Projects/Django/socialnet-v2/env/lib/python3.11/site-packages/django/template/backends/django.py", line 61, in render
    return self.template.render(context)
           ^^^^^^^^^^^^^^^^^^^^^^^^^^^^^
  File "/home/kayprogrammer/Documents/Projects/Django/socialnet-v2/env/lib/python3.11/site-packages/django/template/base.py", line 175, in render
    return self._render(context)
           ^^^^^^^^^^^^^^^^^^^^^
  File "/home/kayprogrammer/Documents/Projects/Django/socialnet-v2/env/lib/python3.11/site-packages/django/test/utils.py", line 112, in instrumented_test_render
    return self.nodelist.render(context)
           ^^^^^^^^^^^^^^^^^^^^^^^^^^^^^
  File "/home/kayprogrammer/Documents/Projects/Django/socialnet-v2/env/lib/python3.11/site-packages/django/template/base.py", line 1005, in render
    return SafeString("".join([node.render_annotated(context) for node in self]))
                              ^^^^^^^^^^^^^^^^^^^^^^^^^^^^^^^^^^^^^^^^^^^^^^^^^
  File "/home/kayprogrammer/Documents/Projects/Django/socialnet-v2/env/lib/python3.11/site-packages/django/template/base.py", line 1005, in <listcomp>
    return SafeString("".join([node.render_annotated(context) for node in self]))
                               ^^^^^^^^^^^^^^^^^^^^^^^^^^^^^^
  File "/home/kayprogrammer/Documents/Projects/Django/socialnet-v2/env/lib/python3.11/site-packages/django/template/base.py", line 966, in render_annotated
    return self.render(context)
           ^^^^^^^^^^^^^^^^^^^^
  File "/home/kayprogrammer/Documents/Projects/Django/socialnet-v2/env/lib/python3.11/site-packages/django/template/defaulttags.py", line 321, in render
    return nodelist.render(context)
           ^^^^^^^^^^^^^^^^^^^^^^^^
  File "/home/kayprogrammer/Documents/Projects/Django/socialnet-v2/env/lib/python3.11/site-packages/django/template/base.py", line 1005, in render
    return SafeString("".join([node.render_annotated(context) for node in self]))
                              ^^^^^^^^^^^^^^^^^^^^^^^^^^^^^^^^^^^^^^^^^^^^^^^^^
  File "/home/kayprogrammer/Documents/Projects/Django/socialnet-v2/env/lib/python3.11/site-packages/django/template/base.py", line 1005, in <listcomp>
    return SafeString("".join([node.render_annotated(context) for node in self]))
                               ^^^^^^^^^^^^^^^^^^^^^^^^^^^^^^
  File "/home/kayprogrammer/Documents/Projects/Django/socialnet-v2/env/lib/python3.11/site-packages/django/template/base.py", line 966, in render_annotated
    return self.render(context)
           ^^^^^^^^^^^^^^^^^^^^
  File "/home/kayprogrammer/Documents/Projects/Django/socialnet-v2/env/lib/python3.11/site-packages/django/template/defaulttags.py", line 238, in render
    nodelist.append(node.render_annotated(context))
                    ^^^^^^^^^^^^^^^^^^^^^^^^^^^^^^
  File "/home/kayprogrammer/Documents/Projects/Django/socialnet-v2/env/lib/python3.11/site-packages/django/template/base.py", line 966, in render_annotated
    return self.render(context)
           ^^^^^^^^^^^^^^^^^^^^
  File "/home/kayprogrammer/Documents/Projects/Django/socialnet-v2/env/lib/python3.11/site-packages/django/template/defaulttags.py", line 471, in render
    url = reverse(view_name, args=args, kwargs=kwargs, current_app=current_app)
          ^^^^^^^^^^^^^^^^^^^^^^^^^^^^^^^^^^^^^^^^^^^^^^^^^^^^^^^^^^^^^^^^^^^^^
  File "/home/kayprogrammer/Documents/Projects/Django/socialnet-v2/env/lib/python3.11/site-packages/django/urls/base.py", line 82, in reverse
    raise NoReverseMatch("%s is not a registered namespace" % key)
django.urls.exceptions.NoReverseMatch: 'djdt' is not a registered namespace
2023-10-10 21:39:35,582 django.request WARNING  Not Found: /
2023-10-10 21:39:36,139 django.request WARNING  Not Found: /favicon.ico
2023-10-10 21:42:22,990 django.request WARNING  Not Found: /
2023-10-10 21:42:24,617 django.request WARNING  Not Found: /
2023-10-10 21:45:02,846 django.request WARNING  Not Found: /static/media/banner2-icon3.png
2023-10-10 21:45:03,455 django.request WARNING  Not Found: /static/media/logo.png
2023-10-10 21:45:07,750 jazzmin.utils WARNING  listings not found when generating links
2023-10-10 21:45:07,754 jazzmin.templatetags.jazzmin WARNING  avatar field must be an ImageField/URLField on the user model, or a callable
2023-10-10 21:45:08,441 django.request WARNING  Not Found: /static/media/banner2-icon3.png
2023-10-10 21:45:13,709 jazzmin.utils WARNING  listings not found when generating links
2023-10-10 21:45:13,711 jazzmin.templatetags.jazzmin WARNING  avatar field must be an ImageField/URLField on the user model, or a callable
2023-10-10 21:45:14,684 django.request WARNING  Not Found: /static/media/banner2-icon3.png
2023-10-10 21:45:38,410 cities_light INFO     Creating /home/kayprogrammer/Documents/Projects/Django/socialnet-v2/env/lib/python3.11/site-packages/cities_light/data
2023-10-10 21:45:39,023 cities_light INFO     Downloading http://download.geonames.org/export/dump/countryInfo.txt into /home/kayprogrammer/Documents/Projects/Django/socialnet-v2/env/lib/python3.11/site-packages/cities_light/data/countryInfo.txt
2023-10-10 21:45:39,778 cities_light INFO     Forced import of countryInfo.txt because data do not seem to have installed successfuly yet, note that this is equivalent to --force-import-all.
2023-10-10 21:45:39,778 cities_light INFO     Importing countryInfo.txt
2023-10-10 21:45:43,631 cities_light INFO     Downloading http://download.geonames.org/export/dump/admin1CodesASCII.txt into /home/kayprogrammer/Documents/Projects/Django/socialnet-v2/env/lib/python3.11/site-packages/cities_light/data/admin1CodesASCII.txt
2023-10-10 21:45:44,693 cities_light INFO     Forced import of admin1CodesASCII.txt because data do not seem to have installed successfuly yet, note that this is equivalent to --force-import-all.
2023-10-10 21:45:44,693 cities_light INFO     Importing admin1CodesASCII.txt
2023-10-10 21:46:46,354 cities_light INFO     Downloading http://download.geonames.org/export/dump/admin2Codes.txt into /home/kayprogrammer/Documents/Projects/Django/socialnet-v2/env/lib/python3.11/site-packages/cities_light/data/admin2Codes.txt
2023-10-10 21:46:56,751 cities_light INFO     Forced import of admin2Codes.txt because data do not seem to have installed successfuly yet, note that this is equivalent to --force-import-all.
2023-10-10 21:46:56,751 cities_light INFO     Importing admin2Codes.txt
2023-10-10 21:48:09,746 jazzmin.utils WARNING  listings not found when generating links
2023-10-10 21:48:09,748 jazzmin.templatetags.jazzmin WARNING  avatar field must be an ImageField/URLField on the user model, or a callable
2023-10-10 21:48:10,791 django.request WARNING  Not Found: /static/media/banner2-icon3.png
2023-10-10 21:48:15,246 jazzmin.utils WARNING  listings not found when generating links
2023-10-10 21:48:15,248 jazzmin.templatetags.jazzmin WARNING  avatar field must be an ImageField/URLField on the user model, or a callable
2023-10-10 21:48:16,219 django.request WARNING  Not Found: /static/media/banner2-icon3.png
2023-10-10 21:48:20,095 jazzmin.utils WARNING  listings not found when generating links
2023-10-10 21:48:20,098 jazzmin.templatetags.jazzmin WARNING  avatar field must be an ImageField/URLField on the user model, or a callable
2023-10-10 21:48:21,260 django.request WARNING  Not Found: /static/media/banner2-icon3.png
2023-10-10 21:48:25,104 jazzmin.utils WARNING  listings not found when generating links
2023-10-10 21:48:25,107 jazzmin.templatetags.jazzmin WARNING  avatar field must be an ImageField/URLField on the user model, or a callable
2023-10-10 21:48:26,035 django.request WARNING  Not Found: /static/media/banner2-icon3.png
2023-10-10 21:48:30,832 jazzmin.utils WARNING  listings not found when generating links
2023-10-10 21:48:30,834 jazzmin.templatetags.jazzmin WARNING  avatar field must be an ImageField/URLField on the user model, or a callable
2023-10-10 21:48:31,717 django.request WARNING  Not Found: /static/media/banner2-icon3.png
2023-10-10 21:48:32,461 jazzmin.utils WARNING  listings not found when generating links
2023-10-10 21:48:32,463 jazzmin.templatetags.jazzmin WARNING  avatar field must be an ImageField/URLField on the user model, or a callable
2023-10-10 21:48:33,557 django.request WARNING  Not Found: /static/media/banner2-icon3.png
2023-10-10 21:48:38,638 jazzmin.utils WARNING  listings not found when generating links
2023-10-10 21:48:38,641 jazzmin.templatetags.jazzmin WARNING  avatar field must be an ImageField/URLField on the user model, or a callable
2023-10-10 21:48:39,690 django.request WARNING  Not Found: /static/media/banner2-icon3.png
2023-10-10 21:48:49,412 cities_light WARNING  Assuming local download is up to date for http://download.geonames.org/export/dump/countryInfo.txt
2023-10-10 21:48:49,412 cities_light INFO     Forced import of countryInfo.txt because data do not seem to have installed successfuly yet, note that this is equivalent to --force-import-all.
2023-10-10 21:48:49,412 cities_light INFO     Importing countryInfo.txt
2023-10-10 21:48:53,660 cities_light WARNING  Assuming local download is up to date for http://download.geonames.org/export/dump/admin1CodesASCII.txt
2023-10-10 21:48:53,660 cities_light INFO     Forced import of admin1CodesASCII.txt because data do not seem to have installed successfuly yet, note that this is equivalent to --force-import-all.
2023-10-10 21:48:53,660 cities_light INFO     Importing admin1CodesASCII.txt
2023-10-10 21:48:58,640 cities_light WARNING  Assuming local download is up to date for http://download.geonames.org/export/dump/admin2Codes.txt
2023-10-10 21:48:58,640 cities_light INFO     Forced import of admin2Codes.txt because data do not seem to have installed successfuly yet, note that this is equivalent to --force-import-all.
2023-10-10 21:48:58,641 cities_light INFO     Importing admin2Codes.txt
2023-10-10 21:50:14,119 jazzmin.utils WARNING  listings not found when generating links
2023-10-10 21:50:14,122 jazzmin.templatetags.jazzmin WARNING  avatar field must be an ImageField/URLField on the user model, or a callable
2023-10-10 21:50:15,331 django.request WARNING  Not Found: /static/media/banner2-icon3.png
2023-10-10 21:50:38,869 jazzmin.utils WARNING  listings not found when generating links
2023-10-10 21:50:38,872 jazzmin.templatetags.jazzmin WARNING  avatar field must be an ImageField/URLField on the user model, or a callable
2023-10-10 21:50:39,950 django.request WARNING  Not Found: /static/media/banner2-icon3.png
2023-10-10 21:50:44,483 jazzmin.utils WARNING  listings not found when generating links
2023-10-10 21:50:44,485 jazzmin.templatetags.jazzmin WARNING  avatar field must be an ImageField/URLField on the user model, or a callable
2023-10-10 21:50:45,551 django.request WARNING  Not Found: /static/media/banner2-icon3.png
2023-10-10 21:50:46,431 jazzmin.utils WARNING  listings not found when generating links
2023-10-10 21:50:46,434 jazzmin.templatetags.jazzmin WARNING  avatar field must be an ImageField/URLField on the user model, or a callable
2023-10-10 21:50:47,410 django.request WARNING  Not Found: /static/media/banner2-icon3.png
2023-10-10 21:51:49,167 jazzmin.utils WARNING  listings not found when generating links
2023-10-10 21:51:49,169 jazzmin.templatetags.jazzmin WARNING  avatar field must be an ImageField/URLField on the user model, or a callable
2023-10-10 21:51:50,210 django.request WARNING  Not Found: /static/media/banner2-icon3.png
2023-10-10 21:51:51,650 jazzmin.utils WARNING  listings not found when generating links
2023-10-10 21:51:51,652 jazzmin.templatetags.jazzmin WARNING  avatar field must be an ImageField/URLField on the user model, or a callable
2023-10-10 21:51:52,705 django.request WARNING  Not Found: /static/media/banner2-icon3.png
2023-10-10 21:52:17,666 cities_light WARNING  Assuming local download is up to date for http://download.geonames.org/export/dump/countryInfo.txt
2023-10-10 21:52:17,668 cities_light INFO     Forced import of countryInfo.txt because data do not seem to have installed successfuly yet, note that this is equivalent to --force-import-all.
2023-10-10 21:52:17,668 cities_light INFO     Importing countryInfo.txt
2023-10-10 21:52:25,611 cities_light WARNING  Assuming local download is up to date for http://download.geonames.org/export/dump/admin1CodesASCII.txt
2023-10-10 21:52:25,612 cities_light INFO     Forced import of admin1CodesASCII.txt because data do not seem to have installed successfuly yet, note that this is equivalent to --force-import-all.
2023-10-10 21:52:25,612 cities_light INFO     Importing admin1CodesASCII.txt
2023-10-10 21:52:31,690 cities_light WARNING  Assuming local download is up to date for http://download.geonames.org/export/dump/admin2Codes.txt
2023-10-10 21:52:31,691 cities_light INFO     Forced import of admin2Codes.txt because data do not seem to have installed successfuly yet, note that this is equivalent to --force-import-all.
2023-10-10 21:52:31,691 cities_light INFO     Importing admin2Codes.txt
2023-10-10 21:54:31,361 jazzmin.utils WARNING  listings not found when generating links
2023-10-10 21:54:31,366 jazzmin.templatetags.jazzmin WARNING  avatar field must be an ImageField/URLField on the user model, or a callable
2023-10-10 21:54:32,529 django.request WARNING  Not Found: /static/media/banner2-icon3.png
2023-10-10 21:55:58,527 django.request WARNING  Not Found: /static/media/banner2-icon3.png
2023-10-10 21:56:09,575 cities_light WARNING  Assuming local download is up to date for http://download.geonames.org/export/dump/countryInfo.txt
2023-10-10 21:56:09,576 cities_light INFO     Forced import of countryInfo.txt because data do not seem to have installed successfuly yet, note that this is equivalent to --force-import-all.
2023-10-10 21:56:09,576 cities_light INFO     Importing countryInfo.txt
2023-10-10 21:56:13,257 cities_light WARNING  Assuming local download is up to date for http://download.geonames.org/export/dump/admin1CodesASCII.txt
2023-10-10 21:56:13,257 cities_light INFO     Forced import of admin1CodesASCII.txt because data do not seem to have installed successfuly yet, note that this is equivalent to --force-import-all.
2023-10-10 21:56:13,258 cities_light INFO     Importing admin1CodesASCII.txt
2023-10-10 21:56:29,641 jazzmin.utils WARNING  listings not found when generating links
2023-10-10 21:56:29,643 jazzmin.templatetags.jazzmin WARNING  avatar field must be an ImageField/URLField on the user model, or a callable
2023-10-10 21:56:30,791 django.request WARNING  Not Found: /static/media/banner2-icon3.png
2023-10-10 21:56:32,742 jazzmin.utils WARNING  listings not found when generating links
2023-10-10 21:56:32,744 jazzmin.templatetags.jazzmin WARNING  avatar field must be an ImageField/URLField on the user model, or a callable
2023-10-10 21:56:33,876 django.request WARNING  Not Found: /static/media/banner2-icon3.png
2023-10-10 21:56:38,588 jazzmin.utils WARNING  listings not found when generating links
2023-10-10 21:56:38,590 jazzmin.templatetags.jazzmin WARNING  avatar field must be an ImageField/URLField on the user model, or a callable
2023-10-10 21:56:39,787 django.request WARNING  Not Found: /static/media/banner2-icon3.png
2023-10-10 21:56:43,266 jazzmin.utils WARNING  listings not found when generating links
2023-10-10 21:56:43,269 jazzmin.templatetags.jazzmin WARNING  avatar field must be an ImageField/URLField on the user model, or a callable
2023-10-10 21:56:44,350 django.request WARNING  Not Found: /static/media/banner2-icon3.png
2023-10-10 21:56:45,939 jazzmin.utils WARNING  listings not found when generating links
2023-10-10 21:56:45,943 jazzmin.templatetags.jazzmin WARNING  avatar field must be an ImageField/URLField on the user model, or a callable
2023-10-10 21:56:46,964 django.request WARNING  Not Found: /static/media/banner2-icon3.png
2023-10-10 21:56:47,987 jazzmin.utils WARNING  listings not found when generating links
2023-10-10 21:56:47,990 jazzmin.templatetags.jazzmin WARNING  avatar field must be an ImageField/URLField on the user model, or a callable
2023-10-10 21:56:49,132 django.request WARNING  Not Found: /static/media/banner2-icon3.png
2023-10-10 21:56:49,905 jazzmin.utils WARNING  listings not found when generating links
2023-10-10 21:56:49,908 jazzmin.templatetags.jazzmin WARNING  avatar field must be an ImageField/URLField on the user model, or a callable
2023-10-10 21:56:51,015 django.request WARNING  Not Found: /static/media/banner2-icon3.png
2023-10-10 21:56:51,532 jazzmin.utils WARNING  listings not found when generating links
2023-10-10 21:56:51,534 jazzmin.templatetags.jazzmin WARNING  avatar field must be an ImageField/URLField on the user model, or a callable
2023-10-10 21:56:52,835 django.request WARNING  Not Found: /static/media/banner2-icon3.png
2023-10-10 21:56:53,149 jazzmin.utils WARNING  listings not found when generating links
2023-10-10 21:56:53,152 jazzmin.templatetags.jazzmin WARNING  avatar field must be an ImageField/URLField on the user model, or a callable
2023-10-10 21:56:54,086 django.request WARNING  Not Found: /static/media/banner2-icon3.png
2023-10-10 21:56:56,899 jazzmin.utils WARNING  listings not found when generating links
2023-10-10 21:56:56,902 jazzmin.templatetags.jazzmin WARNING  avatar field must be an ImageField/URLField on the user model, or a callable
2023-10-10 21:56:58,046 django.request WARNING  Not Found: /static/media/banner2-icon3.png
2023-10-10 21:56:59,962 jazzmin.utils WARNING  listings not found when generating links
2023-10-10 21:56:59,964 jazzmin.templatetags.jazzmin WARNING  avatar field must be an ImageField/URLField on the user model, or a callable
2023-10-10 21:57:01,006 django.request WARNING  Not Found: /static/media/banner2-icon3.png
2023-10-10 21:57:02,752 jazzmin.utils WARNING  listings not found when generating links
2023-10-10 21:57:02,756 jazzmin.templatetags.jazzmin WARNING  avatar field must be an ImageField/URLField on the user model, or a callable
2023-10-10 21:57:03,907 django.request WARNING  Not Found: /static/media/banner2-icon3.png
2023-10-10 21:57:06,410 jazzmin.utils WARNING  listings not found when generating links
2023-10-10 21:57:06,412 jazzmin.templatetags.jazzmin WARNING  avatar field must be an ImageField/URLField on the user model, or a callable
2023-10-10 21:57:07,638 django.request WARNING  Not Found: /static/media/banner2-icon3.png
2023-10-10 21:57:09,270 jazzmin.utils WARNING  listings not found when generating links
2023-10-10 21:57:09,272 jazzmin.templatetags.jazzmin WARNING  avatar field must be an ImageField/URLField on the user model, or a callable
2023-10-10 21:57:10,276 django.request WARNING  Not Found: /static/media/banner2-icon3.png
2023-10-10 21:57:12,088 jazzmin.utils WARNING  listings not found when generating links
2023-10-10 21:57:12,090 jazzmin.templatetags.jazzmin WARNING  avatar field must be an ImageField/URLField on the user model, or a callable
2023-10-10 21:57:13,182 django.request WARNING  Not Found: /static/media/banner2-icon3.png
2023-10-10 21:57:15,428 jazzmin.utils WARNING  listings not found when generating links
2023-10-10 21:57:15,431 jazzmin.templatetags.jazzmin WARNING  avatar field must be an ImageField/URLField on the user model, or a callable
2023-10-10 21:57:16,337 cities_light WARNING  Assuming local download is up to date for http://download.geonames.org/export/dump/admin2Codes.txt
2023-10-10 21:57:16,337 cities_light INFO     Forced import of admin2Codes.txt because data do not seem to have installed successfuly yet, note that this is equivalent to --force-import-all.
2023-10-10 21:57:16,337 cities_light INFO     Importing admin2Codes.txt
2023-10-10 21:57:16,674 django.request WARNING  Not Found: /static/media/banner2-icon3.png
2023-10-10 21:57:18,634 jazzmin.utils WARNING  listings not found when generating links
2023-10-10 21:57:18,637 jazzmin.templatetags.jazzmin WARNING  avatar field must be an ImageField/URLField on the user model, or a callable
2023-10-10 21:57:19,784 django.request WARNING  Not Found: /static/media/banner2-icon3.png
2023-10-10 21:57:20,490 jazzmin.utils WARNING  listings not found when generating links
2023-10-10 21:57:20,492 jazzmin.templatetags.jazzmin WARNING  avatar field must be an ImageField/URLField on the user model, or a callable
2023-10-10 21:57:21,695 django.request WARNING  Not Found: /static/media/banner2-icon3.png
2023-10-10 21:57:22,562 jazzmin.utils WARNING  listings not found when generating links
2023-10-10 21:57:22,564 jazzmin.templatetags.jazzmin WARNING  avatar field must be an ImageField/URLField on the user model, or a callable
2023-10-10 21:57:23,605 django.request WARNING  Not Found: /static/media/banner2-icon3.png
2023-10-10 21:57:28,302 jazzmin.utils WARNING  listings not found when generating links
2023-10-10 21:57:28,305 jazzmin.templatetags.jazzmin WARNING  avatar field must be an ImageField/URLField on the user model, or a callable
2023-10-10 21:57:29,287 django.request WARNING  Not Found: /static/media/banner2-icon3.png
2023-10-10 21:57:31,094 jazzmin.utils WARNING  listings not found when generating links
2023-10-10 21:57:31,097 jazzmin.templatetags.jazzmin WARNING  avatar field must be an ImageField/URLField on the user model, or a callable
2023-10-10 21:57:31,898 django.request WARNING  Not Found: /static/media/banner2-icon3.png
2023-10-10 21:57:33,954 jazzmin.utils WARNING  listings not found when generating links
2023-10-10 21:57:33,958 jazzmin.templatetags.jazzmin WARNING  avatar field must be an ImageField/URLField on the user model, or a callable
2023-10-10 21:57:34,890 django.request WARNING  Not Found: /static/media/banner2-icon3.png
2023-10-10 21:57:44,072 jazzmin.utils WARNING  listings not found when generating links
2023-10-10 21:57:44,074 jazzmin.templatetags.jazzmin WARNING  avatar field must be an ImageField/URLField on the user model, or a callable
2023-10-10 21:57:45,191 django.request WARNING  Not Found: /static/media/banner2-icon3.png
2023-10-10 21:57:54,889 jazzmin.utils WARNING  listings not found when generating links
2023-10-10 21:57:54,891 jazzmin.templatetags.jazzmin WARNING  avatar field must be an ImageField/URLField on the user model, or a callable
2023-10-10 21:57:55,985 django.request WARNING  Not Found: /static/media/banner2-icon3.png
2023-10-10 21:57:58,310 jazzmin.utils WARNING  listings not found when generating links
2023-10-10 21:57:58,314 jazzmin.templatetags.jazzmin WARNING  avatar field must be an ImageField/URLField on the user model, or a callable
2023-10-10 21:57:59,280 django.request WARNING  Not Found: /static/media/banner2-icon3.png
2023-10-10 21:58:01,024 jazzmin.utils WARNING  listings not found when generating links
2023-10-10 21:58:01,026 jazzmin.templatetags.jazzmin WARNING  avatar field must be an ImageField/URLField on the user model, or a callable
2023-10-10 21:58:02,058 django.request WARNING  Not Found: /static/media/banner2-icon3.png
2023-10-10 21:58:04,671 jazzmin.utils WARNING  listings not found when generating links
2023-10-10 21:58:04,673 jazzmin.templatetags.jazzmin WARNING  avatar field must be an ImageField/URLField on the user model, or a callable
2023-10-10 21:58:05,810 django.request WARNING  Not Found: /static/media/banner2-icon3.png
2023-10-10 21:58:06,961 jazzmin.utils WARNING  listings not found when generating links
2023-10-10 21:58:06,965 jazzmin.templatetags.jazzmin WARNING  avatar field must be an ImageField/URLField on the user model, or a callable
2023-10-10 21:58:10,077 jazzmin.utils WARNING  listings not found when generating links
2023-10-10 21:58:10,081 jazzmin.templatetags.jazzmin WARNING  avatar field must be an ImageField/URLField on the user model, or a callable
2023-10-10 21:58:11,075 django.request WARNING  Not Found: /static/media/banner2-icon3.png
2023-10-10 21:58:32,287 jazzmin.utils WARNING  listings not found when generating links
2023-10-10 21:58:32,290 jazzmin.templatetags.jazzmin WARNING  avatar field must be an ImageField/URLField on the user model, or a callable
2023-10-10 21:58:33,296 django.request WARNING  Not Found: /static/media/banner2-icon3.png
2023-10-10 21:58:34,186 jazzmin.utils WARNING  listings not found when generating links
2023-10-10 21:58:34,188 jazzmin.templatetags.jazzmin WARNING  avatar field must be an ImageField/URLField on the user model, or a callable
2023-10-10 21:58:35,214 django.request WARNING  Not Found: /static/media/banner2-icon3.png
2023-10-10 21:58:38,060 jazzmin.utils WARNING  listings not found when generating links
2023-10-10 21:58:38,063 jazzmin.templatetags.jazzmin WARNING  avatar field must be an ImageField/URLField on the user model, or a callable
2023-10-10 21:58:39,026 django.request WARNING  Not Found: /static/media/banner2-icon3.png
2023-10-10 21:58:39,609 jazzmin.utils WARNING  listings not found when generating links
2023-10-10 21:58:39,611 jazzmin.templatetags.jazzmin WARNING  avatar field must be an ImageField/URLField on the user model, or a callable
2023-10-10 21:58:40,748 django.request WARNING  Not Found: /static/media/banner2-icon3.png
2023-10-10 21:58:43,766 jazzmin.utils WARNING  listings not found when generating links
2023-10-10 21:58:43,768 jazzmin.templatetags.jazzmin WARNING  avatar field must be an ImageField/URLField on the user model, or a callable
2023-10-10 21:58:44,833 django.request WARNING  Not Found: /static/media/banner2-icon3.png
2023-10-10 21:59:05,071 jazzmin.utils WARNING  listings not found when generating links
2023-10-10 21:59:05,074 jazzmin.templatetags.jazzmin WARNING  avatar field must be an ImageField/URLField on the user model, or a callable
2023-10-10 21:59:06,115 django.request WARNING  Not Found: /static/media/banner2-icon3.png
2023-10-10 21:59:07,723 jazzmin.utils WARNING  listings not found when generating links
2023-10-10 21:59:07,725 jazzmin.templatetags.jazzmin WARNING  avatar field must be an ImageField/URLField on the user model, or a callable
2023-10-10 21:59:08,789 django.request WARNING  Not Found: /static/media/banner2-icon3.png
2023-10-10 21:59:09,130 jazzmin.utils WARNING  listings not found when generating links
2023-10-10 21:59:09,133 jazzmin.templatetags.jazzmin WARNING  avatar field must be an ImageField/URLField on the user model, or a callable
2023-10-10 21:59:10,046 django.request WARNING  Not Found: /static/media/banner2-icon3.png
2023-10-10 22:08:28,734 cities_light INFO     Downloading http://download.geonames.org/export/dump/cities15000.zip into /home/kayprogrammer/Documents/Projects/Django/socialnet-v2/env/lib/python3.11/site-packages/cities_light/data/cities15000.zip
2023-10-10 22:08:31,950 cities_light INFO     Extracting cities15000.txt from /home/kayprogrammer/Documents/Projects/Django/socialnet-v2/env/lib/python3.11/site-packages/cities_light/data/cities15000.zip into /home/kayprogrammer/Documents/Projects/Django/socialnet-v2/env/lib/python3.11/site-packages/cities_light/data/cities15000.txt
2023-10-10 22:08:32,002 cities_light INFO     Forced import of cities15000.zip because data do not seem to have installed successfuly yet, note that this is equivalent to --force-import-all.
2023-10-10 22:08:32,003 cities_light INFO     Importing cities15000.zip
2023-10-10 22:09:09,627 jazzmin.utils WARNING  listings not found when generating links
2023-10-10 22:09:09,629 jazzmin.templatetags.jazzmin WARNING  avatar field must be an ImageField/URLField on the user model, or a callable
2023-10-10 22:09:12,668 django.request WARNING  Not Found: /static/media/banner2-icon3.png
2023-10-10 22:09:18,547 jazzmin.utils WARNING  listings not found when generating links
2023-10-10 22:09:18,550 jazzmin.templatetags.jazzmin WARNING  avatar field must be an ImageField/URLField on the user model, or a callable
2023-10-10 22:09:21,152 django.request WARNING  Not Found: /static/media/banner2-icon3.png
2023-10-10 22:09:23,431 jazzmin.utils WARNING  listings not found when generating links
2023-10-10 22:09:23,434 jazzmin.templatetags.jazzmin WARNING  avatar field must be an ImageField/URLField on the user model, or a callable
2023-10-10 22:09:26,067 django.request WARNING  Not Found: /static/media/banner2-icon3.png
2023-10-10 22:09:30,317 cities_light WARNING  Saving Zhonghe, Chongqing, China failed: IntegrityError('duplicate key value violates unique constraint "cities_light_city_region_id_subregion_id_name_cdfc77ea_uniq"\nDETAIL:  Key (region_id, subregion_id, name)=(636, 9924, Zhonghe) already exists.')
2023-10-10 22:09:33,452 cities_light WARNING  Saving Xinglong, Chongqing, China failed: IntegrityError('duplicate key value violates unique constraint "cities_light_city_region_id_subregion_id_name_cdfc77ea_uniq"\nDETAIL:  Key (region_id, subregion_id, name)=(636, 9924, Xinglong) already exists.')
2023-10-10 22:09:39,046 cities_light WARNING  Saving Longtan, Chongqing, China failed: IntegrityError('duplicate key value violates unique constraint "cities_light_city_region_id_subregion_id_name_cdfc77ea_uniq"\nDETAIL:  Key (region_id, subregion_id, name)=(636, 9924, Longtan) already exists.')
2023-10-10 22:09:39,737 cities_light WARNING  Saving Linjiang, Chongqing, China failed: IntegrityError('duplicate key value violates unique constraint "cities_light_city_region_id_subregion_id_name_cdfc77ea_uniq"\nDETAIL:  Key (region_id, subregion_id, name)=(636, 9924, Linjiang) already exists.')
2023-10-10 22:09:43,205 cities_light WARNING  Saving Guandu, Chongqing, China failed: IntegrityError('duplicate key value violates unique constraint "cities_light_city_region_id_subregion_id_name_cdfc77ea_uniq"\nDETAIL:  Key (region_id, subregion_id, name)=(636, 9924, Guandu) already exists.')
2023-10-10 22:09:45,620 cities_light WARNING  Saving Longxing, Chongqing, China failed: IntegrityError('duplicate key value violates unique constraint "cities_light_city_region_id_subregion_id_name_cdfc77ea_uniq"\nDETAIL:  Key (region_id, subregion_id, name)=(636, 9924, Longxing) already exists.')
2023-10-10 22:09:46,097 cities_light WARNING  Saving Shuanglong, Chongqing, China failed: IntegrityError('duplicate key value violates unique constraint "cities_light_city_region_id_subregion_id_name_cdfc77ea_uniq"\nDETAIL:  Key (region_id, subregion_id, name)=(636, 9924, Shuanglong) already exists.')
2023-10-10 22:09:47,197 cities_light WARNING  Saving Sanjiao, Chongqing, China failed: IntegrityError('duplicate key value violates unique constraint "cities_light_city_region_id_subregion_id_name_cdfc77ea_uniq"\nDETAIL:  Key (region_id, subregion_id, name)=(636, 9924, Sanjiao) already exists.')
2023-10-10 22:09:47,621 cities_light WARNING  Saving Shima, Chongqing, China failed: IntegrityError('duplicate key value violates unique constraint "cities_light_city_region_id_subregion_id_name_cdfc77ea_uniq"\nDETAIL:  Key (region_id, subregion_id, name)=(636, 9924, Shima) already exists.')
2023-10-10 22:09:47,809 cities_light WARNING  Saving Taiping, Chongqing, China failed: IntegrityError('duplicate key value violates unique constraint "cities_light_city_region_id_subregion_id_name_cdfc77ea_uniq"\nDETAIL:  Key (region_id, subregion_id, name)=(636, 9924, Taiping) already exists.')
2023-10-10 22:09:51,107 cities_light WARNING  Saving E’zhou, Hubei, China failed: IntegrityError('duplicate key value violates unique constraint "cities_light_city_region_id_subregion_id_slug_efb2e768_uniq"\nDETAIL:  Key (region_id, subregion_id, slug)=(627, 9789, ezhou) already exists.')
2023-10-10 22:09:52,627 cities_light WARNING  Saving Wushan, Chongqing, China failed: IntegrityError('duplicate key value violates unique constraint "cities_light_city_region_id_subregion_id_name_cdfc77ea_uniq"\nDETAIL:  Key (region_id, subregion_id, name)=(636, 9924, Wushan) already exists.')
2023-10-10 22:09:52,650 cities_light WARNING  Saving Zhuxi, Chongqing, China failed: IntegrityError('duplicate key value violates unique constraint "cities_light_city_region_id_subregion_id_name_cdfc77ea_uniq"\nDETAIL:  Key (region_id, subregion_id, name)=(636, 9924, Zhuxi) already exists.')
2023-10-10 22:09:52,873 cities_light WARNING  Saving Tai’an, Chongqing, China failed: IntegrityError('duplicate key value violates unique constraint "cities_light_city_region_id_subregion_id_name_cdfc77ea_uniq"\nDETAIL:  Key (region_id, subregion_id, name)=(636, 9924, Tai’an) already exists.')
2023-10-10 22:09:52,996 cities_light WARNING  Saving Xinmin, Chongqing, China failed: IntegrityError('duplicate key value violates unique constraint "cities_light_city_region_id_subregion_id_name_cdfc77ea_uniq"\nDETAIL:  Key (region_id, subregion_id, name)=(636, 9924, Xinmin) already exists.')
2023-10-10 22:09:53,020 cities_light WARNING  Saving Yong’an, Chongqing, China failed: IntegrityError('duplicate key value violates unique constraint "cities_light_city_region_id_subregion_id_name_cdfc77ea_uniq"\nDETAIL:  Key (region_id, subregion_id, name)=(636, 9924, Yong’an) already exists.')
2023-10-10 22:09:53,053 cities_light WARNING  Saving Gaofeng, Chongqing, China failed: IntegrityError('duplicate key value violates unique constraint "cities_light_city_region_id_subregion_id_name_cdfc77ea_uniq"\nDETAIL:  Key (region_id, subregion_id, name)=(636, 9924, Gaofeng) already exists.')
2023-10-10 22:09:53,263 cities_light WARNING  Saving Xinsheng, Chongqing, China failed: IntegrityError('duplicate key value violates unique constraint "cities_light_city_region_id_subregion_id_name_cdfc77ea_uniq"\nDETAIL:  Key (region_id, subregion_id, name)=(636, 9924, Xinsheng) already exists.')
2023-10-10 22:09:53,464 cities_light WARNING  Saving Tonggu, Chongqing, China failed: IntegrityError('duplicate key value violates unique constraint "cities_light_city_region_id_subregion_id_name_cdfc77ea_uniq"\nDETAIL:  Key (region_id, subregion_id, name)=(636, 9924, Tonggu) already exists.')
2023-10-10 22:09:53,531 cities_light WARNING  Saving Sanhe, Chongqing, China failed: IntegrityError('duplicate key value violates unique constraint "cities_light_city_region_id_subregion_id_name_cdfc77ea_uniq"\nDETAIL:  Key (region_id, subregion_id, name)=(636, 9924, Sanhe) already exists.')
2023-10-10 22:09:53,537 cities_light WARNING  Saving Xintian, Chongqing, China failed: IntegrityError('duplicate key value violates unique constraint "cities_light_city_region_id_subregion_id_name_cdfc77ea_uniq"\nDETAIL:  Key (region_id, subregion_id, name)=(636, 9924, Xintian) already exists.')
2023-10-10 22:09:53,675 cities_light WARNING  Saving Yihe, Chongqing, China failed: IntegrityError('duplicate key value violates unique constraint "cities_light_city_region_id_subregion_id_name_cdfc77ea_uniq"\nDETAIL:  Key (region_id, subregion_id, name)=(636, 9924, Yihe) already exists.')
2023-10-10 22:09:53,732 cities_light WARNING  Saving Longhe, Chongqing, China failed: IntegrityError('duplicate key value violates unique constraint "cities_light_city_region_id_subregion_id_name_cdfc77ea_uniq"\nDETAIL:  Key (region_id, subregion_id, name)=(636, 9924, Longhe) already exists.')
2023-10-10 22:09:53,797 cities_light WARNING  Saving Gulu, Chongqing, China failed: IntegrityError('duplicate key value violates unique constraint "cities_light_city_region_id_subregion_id_name_cdfc77ea_uniq"\nDETAIL:  Key (region_id, subregion_id, name)=(636, 9924, Gulu) already exists.')
2023-10-10 22:09:54,020 cities_light WARNING  Saving Longfeng, Chongqing, China failed: IntegrityError('duplicate key value violates unique constraint "cities_light_city_region_id_subregion_id_name_cdfc77ea_uniq"\nDETAIL:  Key (region_id, subregion_id, name)=(636, 9924, Longfeng) already exists.')
2023-10-10 22:09:54,026 cities_light WARNING  Saving Longxing, Chongqing, China failed: IntegrityError('duplicate key value violates unique constraint "cities_light_city_region_id_subregion_id_name_cdfc77ea_uniq"\nDETAIL:  Key (region_id, subregion_id, name)=(636, 9924, Longxing) already exists.')
2023-10-10 22:09:55,600 cities_light WARNING  Saving Shizuishan, Ningxia Hui Autonomous Region, China failed: IntegrityError('duplicate key value violates unique constraint "cities_light_city_region_id_subregion_id_name_cdfc77ea_uniq"\nDETAIL:  Key (region_id, subregion_id, name)=(623, 9697, Shizuishan) already exists.')
2023-10-10 22:09:57,414 cities_light WARNING  Saving Liangping, Chongqing, China failed: IntegrityError('duplicate key value violates unique constraint "cities_light_city_region_id_subregion_id_name_cdfc77ea_uniq"\nDETAIL:  Key (region_id, subregion_id, name)=(636, 9924, Liangping) already exists.')
2023-10-10 22:09:57,419 cities_light WARNING  Saving Xinglong, Chongqing, China failed: IntegrityError('duplicate key value violates unique constraint "cities_light_city_region_id_subregion_id_name_cdfc77ea_uniq"\nDETAIL:  Key (region_id, subregion_id, name)=(636, 9924, Xinglong) already exists.')
2023-10-10 22:10:02,898 cities_light WARNING  Saving Buenaventura, Valle del Cauca, Colombia failed: IntegrityError('duplicate key value violates unique constraint "cities_light_city_region_id_subregion_id_name_cdfc77ea_uniq"\nDETAIL:  Key (region_id, subregion_id, name)=(645, 10949, Buenaventura) already exists.')
2023-10-10 22:10:57,229 cities_light WARNING  Saving Hayes, England, United Kingdom failed: IntegrityError('duplicate key value violates unique constraint "cities_light_city_region_id_subregion_id_name_cdfc77ea_uniq"\nDETAIL:  Key (region_id, subregion_id, name)=(1028, 13468, Hayes) already exists.')
2023-10-10 22:11:20,464 jazzmin.utils WARNING  listings not found when generating links
2023-10-10 22:11:20,466 jazzmin.templatetags.jazzmin WARNING  avatar field must be an ImageField/URLField on the user model, or a callable
2023-10-10 22:11:23,173 django.request WARNING  Not Found: /static/media/banner2-icon3.png
2023-10-10 22:12:57,106 jazzmin.utils WARNING  listings not found when generating links
2023-10-10 22:12:57,108 jazzmin.templatetags.jazzmin WARNING  avatar field must be an ImageField/URLField on the user model, or a callable
2023-10-10 22:12:59,966 django.request WARNING  Not Found: /static/media/banner2-icon3.png
2023-10-10 22:13:07,932 jazzmin.utils WARNING  listings not found when generating links
2023-10-10 22:13:07,935 jazzmin.templatetags.jazzmin WARNING  avatar field must be an ImageField/URLField on the user model, or a callable
2023-10-10 22:13:10,710 django.request WARNING  Not Found: /static/media/banner2-icon3.png
2023-10-10 22:13:13,377 cities_light WARNING  Saving Panauti, Bagmati Province, Nepal failed: IntegrityError('duplicate key value violates unique constraint "cities_light_city_region_id_subregion_id_slug_efb2e768_uniq"\nDETAIL:  Key (region_id, subregion_id, slug)=(2414, 27935, panauti) already exists.')
2023-10-10 22:13:16,766 jazzmin.utils WARNING  listings not found when generating links
2023-10-10 22:13:16,769 jazzmin.templatetags.jazzmin WARNING  avatar field must be an ImageField/URLField on the user model, or a callable
2023-10-10 22:13:19,555 django.request WARNING  Not Found: /static/media/banner2-icon3.png
2023-10-10 22:15:13,470 jazzmin.utils WARNING  listings not found when generating links
2023-10-10 22:15:13,473 jazzmin.templatetags.jazzmin WARNING  avatar field must be an ImageField/URLField on the user model, or a callable
2023-10-10 22:15:16,337 django.request WARNING  Not Found: /static/media/banner2-icon3.png
2023-10-10 22:15:16,476 cities_light WARNING  Saving Vincent, California, United States failed: IntegrityError('duplicate key value violates unique constraint "cities_light_city_region_id_subregion_id_name_cdfc77ea_uniq"\nDETAIL:  Key (region_id, subregion_id, name)=(3637, 42283, Vincent) already exists.')
2023-10-10 22:15:30,237 cities_light INFO     Downloading http://download.geonames.org/export/dump/alternateNames.zip into /home/kayprogrammer/Documents/Projects/Django/socialnet-v2/env/lib/python3.11/site-packages/cities_light/data/alternateNames.zip
2023-10-10 22:16:27,474 jazzmin.utils WARNING  listings not found when generating links
2023-10-10 22:16:27,476 jazzmin.templatetags.jazzmin WARNING  avatar field must be an ImageField/URLField on the user model, or a callable
2023-10-10 22:16:30,191 django.request WARNING  Not Found: /static/media/banner2-icon3.png
2023-10-10 22:18:01,760 cities_light INFO     Extracting alternateNames.txt from /home/kayprogrammer/Documents/Projects/Django/socialnet-v2/env/lib/python3.11/site-packages/cities_light/data/alternateNames.zip into /home/kayprogrammer/Documents/Projects/Django/socialnet-v2/env/lib/python3.11/site-packages/cities_light/data/alternateNames.txt
2023-10-10 22:18:05,149 cities_light INFO     Forced import of alternateNames.zip because data do not seem to have installed successfuly yet, note that this is equivalent to --force-import-all.
2023-10-10 22:18:05,149 cities_light INFO     Importing alternateNames.zip
2023-10-10 22:18:07,956 jazzmin.utils WARNING  listings not found when generating links
2023-10-10 22:18:07,959 jazzmin.templatetags.jazzmin WARNING  avatar field must be an ImageField/URLField on the user model, or a callable
2023-10-10 22:18:10,913 django.request WARNING  Not Found: /static/media/banner2-icon3.png
2023-10-10 22:18:14,398 jazzmin.utils WARNING  listings not found when generating links
2023-10-10 22:18:14,402 jazzmin.templatetags.jazzmin WARNING  avatar field must be an ImageField/URLField on the user model, or a callable
2023-10-10 22:18:17,476 django.request WARNING  Not Found: /static/media/banner2-icon3.png
2023-10-10 22:18:19,661 jazzmin.utils WARNING  listings not found when generating links
2023-10-10 22:18:19,666 jazzmin.templatetags.jazzmin WARNING  avatar field must be an ImageField/URLField on the user model, or a callable
2023-10-10 22:18:22,384 django.request WARNING  Not Found: /static/media/banner2-icon3.png
2023-10-10 22:18:27,050 jazzmin.utils WARNING  listings not found when generating links
2023-10-10 22:18:27,052 jazzmin.templatetags.jazzmin WARNING  avatar field must be an ImageField/URLField on the user model, or a callable
2023-10-10 22:18:29,484 django.request WARNING  Not Found: /static/media/banner2-icon3.png
2023-10-11 16:15:38,906 jazzmin.utils WARNING  listings not found when generating links
2023-10-11 16:15:39,014 jazzmin.templatetags.jazzmin WARNING  avatar field must be an ImageField/URLField on the user model, or a callable
2023-10-11 16:15:44,056 django.request WARNING  Not Found: /static/media/banner2-icon3.png
2023-10-11 16:15:45,261 django.request WARNING  Not Found: /static/media/logo.png
2023-10-11 17:03:41,059 django       ERROR    null value in column "access" violates not-null constraint
DETAIL:  Failing row contains (pbkdf2_sha256$600000$c8hdw0Rh8f3ScmNjIIxyWl$T1GmbwcV0ZkECcdxOs7s..., null, f, 21fd92c2-3054-41c9-8b05-842ecdf831c6, John, Doe, john-doe, kenechiifeanyi@gmail.com, t, f, f, t, 2023-10-11 16:03:41.033277+00, 2023-10-11 16:03:41.0333+00, null, null, null, null, null, null).
Traceback (most recent call last):
  File "/home/kayprogrammer/Documents/Projects/Django/socialnet-v2/env/lib/python3.11/site-packages/django/db/backends/utils.py", line 89, in _execute
    return self.cursor.execute(sql, params)
           ^^^^^^^^^^^^^^^^^^^^^^^^^^^^^^^^
  File "/home/kayprogrammer/Documents/Projects/Django/socialnet-v2/env/lib/python3.11/site-packages/psycopg/cursor.py", line 723, in execute
    raise ex.with_traceback(None)
psycopg.errors.NotNullViolation: null value in column "access" violates not-null constraint
DETAIL:  Failing row contains (pbkdf2_sha256$600000$c8hdw0Rh8f3ScmNjIIxyWl$T1GmbwcV0ZkECcdxOs7s..., null, f, 21fd92c2-3054-41c9-8b05-842ecdf831c6, John, Doe, john-doe, kenechiifeanyi@gmail.com, t, f, f, t, 2023-10-11 16:03:41.033277+00, 2023-10-11 16:03:41.0333+00, null, null, null, null, null, null).

The above exception was the direct cause of the following exception:

Traceback (most recent call last):
  File "/home/kayprogrammer/Documents/Projects/Django/socialnet-v2/env/lib/python3.11/site-packages/ninja/operation.py", line 265, in run
    result = await self.view_func(request, **values)
             ^^^^^^^^^^^^^^^^^^^^^^^^^^^^^^^^^^^^^^^
  File "/home/kayprogrammer/Documents/Projects/Django/socialnet-v2/apps/accounts/views.py", line 46, in register
    user = await User.objects.acreate_user(**data.dict())
           ^^^^^^^^^^^^^^^^^^^^^^^^^^^^^^^^^^^^^^^^^^^^^^
  File "/home/kayprogrammer/Documents/Projects/Django/socialnet-v2/apps/accounts/managers.py", line 70, in acreate_user
    await user.asave(using=self._db)
  File "/home/kayprogrammer/Documents/Projects/Django/socialnet-v2/env/lib/python3.11/site-packages/django/db/models/base.py", line 826, in asave
    return await sync_to_async(self.save)(
           ^^^^^^^^^^^^^^^^^^^^^^^^^^^^^^^
  File "/home/kayprogrammer/Documents/Projects/Django/socialnet-v2/env/lib/python3.11/site-packages/asgiref/sync.py", line 479, in __call__
    ret: _R = await loop.run_in_executor(
              ^^^^^^^^^^^^^^^^^^^^^^^^^^^
  File "/home/kayprogrammer/Documents/Projects/Django/socialnet-v2/env/lib/python3.11/site-packages/asgiref/current_thread_executor.py", line 40, in run
    result = self.fn(*self.args, **self.kwargs)
             ^^^^^^^^^^^^^^^^^^^^^^^^^^^^^^^^^^
  File "/home/kayprogrammer/Documents/Projects/Django/socialnet-v2/env/lib/python3.11/site-packages/asgiref/sync.py", line 538, in thread_handler
    return func(*args, **kwargs)
           ^^^^^^^^^^^^^^^^^^^^^
  File "/home/kayprogrammer/Documents/Projects/Django/socialnet-v2/env/lib/python3.11/site-packages/django/contrib/auth/base_user.py", line 76, in save
    super().save(*args, **kwargs)
  File "/home/kayprogrammer/Documents/Projects/Django/socialnet-v2/env/lib/python3.11/site-packages/django/db/models/base.py", line 814, in save
    self.save_base(
  File "/home/kayprogrammer/Documents/Projects/Django/socialnet-v2/env/lib/python3.11/site-packages/django/db/models/base.py", line 877, in save_base
    updated = self._save_table(
              ^^^^^^^^^^^^^^^^^
  File "/home/kayprogrammer/Documents/Projects/Django/socialnet-v2/env/lib/python3.11/site-packages/django/db/models/base.py", line 1020, in _save_table
    results = self._do_insert(
              ^^^^^^^^^^^^^^^^
  File "/home/kayprogrammer/Documents/Projects/Django/socialnet-v2/env/lib/python3.11/site-packages/django/db/models/base.py", line 1061, in _do_insert
    return manager._insert(
           ^^^^^^^^^^^^^^^^
  File "/home/kayprogrammer/Documents/Projects/Django/socialnet-v2/env/lib/python3.11/site-packages/django/db/models/manager.py", line 87, in manager_method
    return getattr(self.get_queryset(), name)(*args, **kwargs)
           ^^^^^^^^^^^^^^^^^^^^^^^^^^^^^^^^^^^^^^^^^^^^^^^^^^^
  File "/home/kayprogrammer/Documents/Projects/Django/socialnet-v2/env/lib/python3.11/site-packages/django/db/models/query.py", line 1805, in _insert
    return query.get_compiler(using=using).execute_sql(returning_fields)
           ^^^^^^^^^^^^^^^^^^^^^^^^^^^^^^^^^^^^^^^^^^^^^^^^^^^^^^^^^^^^^
  File "/home/kayprogrammer/Documents/Projects/Django/socialnet-v2/env/lib/python3.11/site-packages/django/db/models/sql/compiler.py", line 1822, in execute_sql
    cursor.execute(sql, params)
  File "/home/kayprogrammer/Documents/Projects/Django/socialnet-v2/env/lib/python3.11/site-packages/debug_toolbar/panels/sql/tracking.py", line 252, in execute
    return self._record(super().execute, sql, params)
           ^^^^^^^^^^^^^^^^^^^^^^^^^^^^^^^^^^^^^^^^^^
  File "/home/kayprogrammer/Documents/Projects/Django/socialnet-v2/env/lib/python3.11/site-packages/debug_toolbar/panels/sql/tracking.py", line 177, in _record
    return method(sql, params)
           ^^^^^^^^^^^^^^^^^^^
  File "/home/kayprogrammer/Documents/Projects/Django/socialnet-v2/env/lib/python3.11/site-packages/django/db/backends/utils.py", line 102, in execute
    return super().execute(sql, params)
           ^^^^^^^^^^^^^^^^^^^^^^^^^^^^
  File "/home/kayprogrammer/Documents/Projects/Django/socialnet-v2/env/lib/python3.11/site-packages/django/db/backends/utils.py", line 67, in execute
    return self._execute_with_wrappers(
           ^^^^^^^^^^^^^^^^^^^^^^^^^^^^
  File "/home/kayprogrammer/Documents/Projects/Django/socialnet-v2/env/lib/python3.11/site-packages/django/db/backends/utils.py", line 80, in _execute_with_wrappers
    return executor(sql, params, many, context)
           ^^^^^^^^^^^^^^^^^^^^^^^^^^^^^^^^^^^^
  File "/home/kayprogrammer/Documents/Projects/Django/socialnet-v2/env/lib/python3.11/site-packages/django/db/backends/utils.py", line 84, in _execute
    with self.db.wrap_database_errors:
  File "/home/kayprogrammer/Documents/Projects/Django/socialnet-v2/env/lib/python3.11/site-packages/django/db/utils.py", line 91, in __exit__
    raise dj_exc_value.with_traceback(traceback) from exc_value
  File "/home/kayprogrammer/Documents/Projects/Django/socialnet-v2/env/lib/python3.11/site-packages/django/db/backends/utils.py", line 89, in _execute
    return self.cursor.execute(sql, params)
           ^^^^^^^^^^^^^^^^^^^^^^^^^^^^^^^^
  File "/home/kayprogrammer/Documents/Projects/Django/socialnet-v2/env/lib/python3.11/site-packages/psycopg/cursor.py", line 723, in execute
    raise ex.with_traceback(None)
django.db.utils.IntegrityError: null value in column "access" violates not-null constraint
DETAIL:  Failing row contains (pbkdf2_sha256$600000$c8hdw0Rh8f3ScmNjIIxyWl$T1GmbwcV0ZkECcdxOs7s..., null, f, 21fd92c2-3054-41c9-8b05-842ecdf831c6, John, Doe, john-doe, kenechiifeanyi@gmail.com, t, f, f, t, 2023-10-11 16:03:41.033277+00, 2023-10-11 16:03:41.0333+00, null, null, null, null, null, null).
2023-10-11 17:03:41,195 django.request ERROR    Internal Server Error: /api/v2/auth/register/
2023-10-11 17:05:05,026 jazzmin.utils WARNING  listings not found when generating links
2023-10-11 17:05:05,030 jazzmin.templatetags.jazzmin WARNING  avatar field must be an ImageField/URLField on the user model, or a callable
2023-10-11 17:05:08,307 django.request WARNING  Not Found: /static/media/banner2-icon3.png
2023-10-11 17:05:10,731 jazzmin.utils WARNING  listings not found when generating links
2023-10-11 17:05:10,733 jazzmin.templatetags.jazzmin WARNING  avatar field must be an ImageField/URLField on the user model, or a callable
2023-10-11 17:05:12,075 django.request WARNING  Not Found: /static/media/banner2-icon3.png
2023-10-11 17:05:18,126 jazzmin.utils WARNING  listings not found when generating links
2023-10-11 17:05:18,129 jazzmin.templatetags.jazzmin WARNING  avatar field must be an ImageField/URLField on the user model, or a callable
2023-10-11 17:05:19,298 django.request WARNING  Not Found: /static/media/banner2-icon3.png
2023-10-11 17:05:21,436 django.request WARNING  Not Found: /static/media/banner2-icon3.png
2023-10-11 17:07:02,093 django.request WARNING  Not Found: /api/v2/auth/verify-email/
2023-10-11 17:07:11,839 django.request WARNING  Unprocessable Entity: /api/v2/auth/register/
2023-10-11 17:09:41,441 django.request WARNING  Unauthorized: /api/v2/auth/login/
2023-10-11 17:09:43,955 django.request WARNING  Unauthorized: /api/v2/auth/login/
2023-10-11 17:10:15,613 django       ERROR    RequestError.__init__() missing 1 required positional argument: 'err_code'
Traceback (most recent call last):
  File "/home/kayprogrammer/Documents/Projects/Django/socialnet-v2/env/lib/python3.11/site-packages/ninja/operation.py", line 265, in run
    result = await self.view_func(request, **values)
             ^^^^^^^^^^^^^^^^^^^^^^^^^^^^^^^^^^^^^^^
  File "/home/kayprogrammer/Documents/Projects/Django/socialnet-v2/apps/accounts/views.py", line 236, in refresh
    raise RequestError(
          ^^^^^^^^^^^^^
TypeError: RequestError.__init__() missing 1 required positional argument: 'err_code'
2023-10-11 17:10:15,667 django.request ERROR    Internal Server Error: /api/v2/auth/refresh/
2023-10-11 17:10:58,482 django.request WARNING  Unauthorized: /api/v2/auth/refresh/
2023-10-11 17:10:59,485 django.request WARNING  Unauthorized: /api/v2/auth/refresh/
2023-10-11 17:11:44,480 django.request WARNING  Unauthorized: /api/v2/auth/logout/
2023-10-11 17:11:51,636 django       ERROR    object NoneType can't be used in 'await' expression
Traceback (most recent call last):
  File "/home/kayprogrammer/Documents/Projects/Django/socialnet-v2/env/lib/python3.11/site-packages/ninja/operation.py", line 265, in run
    result = await self.view_func(request, **values)
             ^^^^^^^^^^^^^^^^^^^^^^^^^^^^^^^^^^^^^^^
  File "/home/kayprogrammer/Documents/Projects/Django/socialnet-v2/apps/accounts/views.py", line 264, in logout
    user = await request.auth
           ^^^^^^^^^^^^^^^^^^
  File "/home/kayprogrammer/Documents/Projects/Django/socialnet-v2/apps/common/utils.py", line 12, in authenticate
    user = await Authentication.decodeAuthorization(token)
           ^^^^^^^^^^^^^^^^^^^^^^^^^^^^^^^^^^^^^^^^^^^^^^^
TypeError: object NoneType can't be used in 'await' expression
2023-10-11 17:11:51,681 django.request ERROR    Internal Server Error: /api/v2/auth/logout/
2023-10-11 17:13:20,548 django       ERROR    RequestError.__init__() missing 1 required positional argument: 'err_code'
Traceback (most recent call last):
  File "/home/kayprogrammer/Documents/Projects/Django/socialnet-v2/env/lib/python3.11/site-packages/ninja/operation.py", line 265, in run
    result = await self.view_func(request, **values)
             ^^^^^^^^^^^^^^^^^^^^^^^^^^^^^^^^^^^^^^^
  File "/home/kayprogrammer/Documents/Projects/Django/socialnet-v2/apps/accounts/views.py", line 264, in logout
    user = await request.auth
           ^^^^^^^^^^^^^^^^^^
  File "/home/kayprogrammer/Documents/Projects/Django/socialnet-v2/apps/common/utils.py", line 14, in authenticate
    raise RequestError(
          ^^^^^^^^^^^^^
TypeError: RequestError.__init__() missing 1 required positional argument: 'err_code'
2023-10-11 17:13:20,699 django.request ERROR    Internal Server Error: /api/v2/auth/logout/
2023-10-11 17:14:02,747 django.request WARNING  Unauthorized: /api/v2/auth/logout/
2023-10-11 17:14:06,669 django.request WARNING  Unauthorized: /api/v2/auth/logout/
2023-10-11 17:14:33,840 django.request WARNING  Unauthorized: /api/v2/auth/logout/
2023-10-11 17:14:38,700 django.request WARNING  Unauthorized: /api/v2/auth/logout/
2023-10-11 17:14:50,667 django.request WARNING  Unauthorized: /api/v2/auth/logout/
2023-10-11 17:15:27,982 django.request WARNING  Unauthorized: /api/v2/auth/logout/
2023-10-11 17:16:01,629 django.request WARNING  Unauthorized: /api/v2/auth/logout/
2023-10-11 17:20:17,424 django.request WARNING  Unauthorized: /api/v2/auth/refresh/
2023-10-11 17:20:31,899 django.request WARNING  Unauthorized: /api/v2/auth/refresh/
2023-10-11 17:21:58,283 django.request WARNING  Unauthorized: /api/v2/auth/logout/
2023-10-11 17:22:51,196 django.request WARNING  Unauthorized: /api/v2/auth/logout/
2023-10-11 17:23:55,418 django.request WARNING  Unauthorized: /api/v2/auth/logout/
2023-10-11 17:24:12,355 django.request WARNING  Unauthorized: /api/v2/auth/logout/
2023-10-11 17:24:22,619 django       ERROR    You cannot call this from an async context - use a thread or sync_to_async.
Traceback (most recent call last):
  File "/home/kayprogrammer/Documents/Projects/Django/socialnet-v2/env/lib/python3.11/site-packages/ninja/operation.py", line 265, in run
    result = await self.view_func(request, **values)
             ^^^^^^^^^^^^^^^^^^^^^^^^^^^^^^^^^^^^^^^
  File "/home/kayprogrammer/Documents/Projects/Django/socialnet-v2/apps/accounts/views.py", line 266, in logout
    user = await request.auth
           ^^^^^^^^^^^^^^^^^^
  File "/home/kayprogrammer/Documents/Projects/Django/socialnet-v2/apps/common/utils.py", line 17, in authenticate
    user = Authentication.decodeAuthorization(token)
           ^^^^^^^^^^^^^^^^^^^^^^^^^^^^^^^^^^^^^^^^^
  File "/home/kayprogrammer/Documents/Projects/Django/socialnet-v2/apps/accounts/auth.py", line 49, in decodeAuthorization
    ).get_or_none(id=decoded["user_id"])
      ^^^^^^^^^^^^^^^^^^^^^^^^^^^^^^^^^^
  File "/home/kayprogrammer/Documents/Projects/Django/socialnet-v2/apps/common/managers.py", line 9, in get_or_none
    return self.get(**kwargs)
           ^^^^^^^^^^^^^^^^^^
  File "/home/kayprogrammer/Documents/Projects/Django/socialnet-v2/env/lib/python3.11/site-packages/django/db/models/query.py", line 633, in get
    num = len(clone)
          ^^^^^^^^^^
  File "/home/kayprogrammer/Documents/Projects/Django/socialnet-v2/env/lib/python3.11/site-packages/django/db/models/query.py", line 380, in __len__
    self._fetch_all()
  File "/home/kayprogrammer/Documents/Projects/Django/socialnet-v2/env/lib/python3.11/site-packages/django/db/models/query.py", line 1881, in _fetch_all
    self._result_cache = list(self._iterable_class(self))
                         ^^^^^^^^^^^^^^^^^^^^^^^^^^^^^^^^
  File "/home/kayprogrammer/Documents/Projects/Django/socialnet-v2/env/lib/python3.11/site-packages/django/db/models/query.py", line 91, in __iter__
    results = compiler.execute_sql(
              ^^^^^^^^^^^^^^^^^^^^^
  File "/home/kayprogrammer/Documents/Projects/Django/socialnet-v2/env/lib/python3.11/site-packages/django/db/models/sql/compiler.py", line 1560, in execute_sql
    cursor = self.connection.cursor()
             ^^^^^^^^^^^^^^^^^^^^^^^^
  File "/home/kayprogrammer/Documents/Projects/Django/socialnet-v2/env/lib/python3.11/site-packages/django/utils/asyncio.py", line 24, in inner
    raise SynchronousOnlyOperation(message)
django.core.exceptions.SynchronousOnlyOperation: You cannot call this from an async context - use a thread or sync_to_async.
2023-10-11 17:24:22,839 django.request ERROR    Internal Server Error: /api/v2/auth/logout/
2023-10-11 17:25:58,864 django.request WARNING  Unauthorized: /api/v2/auth/logout/
2023-10-11 17:26:00,440 django.request WARNING  Unauthorized: /api/v2/auth/logout/
2023-10-11 17:26:41,819 django.request WARNING  Unauthorized: /api/v2/auth/logout/
2023-10-12 16:02:34,268 django.request WARNING  Not Found: /static/media/banner2-icon3.png
2023-10-12 16:02:34,988 django.request WARNING  Not Found: /static/media/logo.png
2023-10-12 16:09:28,685 django.request WARNING  Bad Request: /api/v2/auth/register/
2023-10-12 16:10:15,446 django.request WARNING  Bad Request: /api/v2/auth/register/
2023-10-12 16:11:14,386 django.request WARNING  Bad Request: /api/v2/auth/register/
2023-10-12 16:13:13,061 django.request WARNING  Bad Request: /api/v2/auth/register/
2023-10-12 16:20:44,035 django.request WARNING  Unprocessable Entity: /api/v2/auth/register/
2023-10-12 16:28:54,070 django.request WARNING  Not Found: /api/v2/auth/send-password-reset-otp/
2023-10-12 16:28:54,902 django.request WARNING  Unauthorized: /api/v2/auth/login/
2023-10-12 16:28:55,316 django.request WARNING  Unauthorized: /api/v2/auth/login/
2023-10-12 16:30:53,853 django.request WARNING  Not Found: /api/v2/auth/send-password-reset-otp/
2023-10-12 16:30:54,682 django.request WARNING  Unauthorized: /api/v2/auth/login/
2023-10-12 16:30:55,099 django.request WARNING  Unauthorized: /api/v2/auth/login/
2023-10-12 16:30:56,353 django.request WARNING  Unauthorized: /api/v2/auth/logout/
2023-10-12 16:32:08,036 django.request WARNING  Not Found: /api/v2/auth/send-password-reset-otp/
2023-10-12 16:32:08,907 django.request WARNING  Unauthorized: /api/v2/auth/login/
2023-10-12 16:32:09,313 django.request WARNING  Unauthorized: /api/v2/auth/login/
2023-10-12 16:32:10,598 django.request WARNING  Unauthorized: /api/v2/auth/logout/
2023-10-12 16:35:23,147 django.request WARNING  Not Found: /api/v2/auth/send-password-reset-otp/
2023-10-12 16:35:24,007 django.request WARNING  Unauthorized: /api/v2/auth/login/
2023-10-12 16:35:24,429 django.request WARNING  Unauthorized: /api/v2/auth/login/
2023-10-12 16:35:25,684 django.request WARNING  Unauthorized: /api/v2/auth/logout/
2023-10-12 16:36:15,401 django.request WARNING  Not Found: /api/v2/auth/send-password-reset-otp/
2023-10-12 16:36:16,343 django.request WARNING  Unauthorized: /api/v2/auth/login/
2023-10-12 16:36:16,825 django.request WARNING  Unauthorized: /api/v2/auth/login/
2023-10-12 16:36:18,067 django.request WARNING  Unauthorized: /api/v2/auth/logout/
2023-10-12 16:37:29,159 django.request WARNING  Not Found: /api/v2/auth/send-password-reset-otp/
2023-10-12 16:37:29,988 django.request WARNING  Unauthorized: /api/v2/auth/login/
2023-10-12 16:37:30,392 django.request WARNING  Unauthorized: /api/v2/auth/login/
2023-10-12 16:37:31,654 django.request WARNING  Unauthorized: /api/v2/auth/logout/
2023-10-12 16:45:15,466 django.request WARNING  Not Found: /api/v2/auth/send-password-reset-otp/
2023-10-12 16:45:16,292 django.request WARNING  Unauthorized: /api/v2/auth/login/
2023-10-12 16:45:16,723 django.request WARNING  Unauthorized: /api/v2/auth/login/
2023-10-12 16:45:17,992 django.request WARNING  Unauthorized: /api/v2/auth/logout/
2023-10-12 16:46:23,748 django.request WARNING  Not Found: /api/v2/auth/send-password-reset-otp/
2023-10-12 16:46:24,579 django.request WARNING  Unauthorized: /api/v2/auth/login/
2023-10-12 16:46:24,976 django.request WARNING  Unauthorized: /api/v2/auth/login/
2023-10-12 16:46:26,243 django.request WARNING  Unauthorized: /api/v2/auth/logout/
2023-10-12 16:46:52,092 django.request WARNING  Not Found: /api/v2/auth/send-password-reset-otp/
2023-10-12 16:46:52,904 django.request WARNING  Unauthorized: /api/v2/auth/login/
2023-10-12 16:46:53,305 django.request WARNING  Unauthorized: /api/v2/auth/login/
2023-10-12 16:46:54,535 django.request WARNING  Unauthorized: /api/v2/auth/logout/
2023-10-12 16:46:55,372 django.request WARNING  Unauthorized: /api/v2/auth/refresh/
2023-10-12 16:46:56,584 django.request WARNING  Unprocessable Entity: /api/v2/auth/register/
2023-10-12 16:46:57,420 django.request WARNING  Not Found: /api/v2/auth/resend-verification-email/
2023-10-12 16:46:58,253 django.request WARNING  Not Found: /api/v2/auth/set-new-password/
2023-10-12 16:46:58,261 django.request WARNING  Not Found: /api/v2/auth/set-new-password/
2023-10-12 16:46:59,534 django.request WARNING  Not Found: /api/v2/auth/verify-email/
2023-10-12 16:48:12,615 django.request WARNING  Not Found: /api/v1/general/site-detail/
2023-10-13 11:36:23,868 django       ERROR    'ASGIRequest' object has no attribute 'auth'
Traceback (most recent call last):
  File "/home/kayprogrammer/Documents/Projects/Django/socialnet-v2/env/lib/python3.11/site-packages/ninja/operation.py", line 265, in run
    result = await self.view_func(request, **values)
             ^^^^^^^^^^^^^^^^^^^^^^^^^^^^^^^^^^^^^^^
  File "/home/kayprogrammer/Documents/Projects/Django/socialnet-v2/apps/profiles/views.py", line 61, in retrieve_users
    user = await request.auth
                 ^^^^^^^^^^^^
AttributeError: 'ASGIRequest' object has no attribute 'auth'
2023-10-13 11:36:23,997 django.request ERROR    Internal Server Error: /api/v2/profiles/
2023-10-13 11:50:21,625 django.request WARNING  Unauthorized: /api/v2/profiles/
2023-10-13 11:53:43,900 django.request WARNING  Unauthorized: /api/v2/profiles/
2023-10-13 12:05:08,605 django       ERROR    AuthBase.__init__() takes 1 positional argument but 2 were given
Traceback (most recent call last):
  File "/home/kayprogrammer/Documents/Projects/Django/socialnet-v2/env/lib/python3.11/site-packages/ninja/operation.py", line 292, in _run_authentication
    result = callback(request)
             ^^^^^^^^^^^^^^^^^
TypeError: AuthBase.__init__() takes 1 positional argument but 2 were given
2023-10-13 12:05:08,650 django.request ERROR    Internal Server Error: /api/v2/profiles/
2023-10-13 12:05:44,918 django       ERROR    AuthBase.__init__() takes 1 positional argument but 2 were given
Traceback (most recent call last):
  File "/home/kayprogrammer/Documents/Projects/Django/socialnet-v2/env/lib/python3.11/site-packages/ninja/operation.py", line 292, in _run_authentication
    result = callback(request)
             ^^^^^^^^^^^^^^^^^
TypeError: AuthBase.__init__() takes 1 positional argument but 2 were given
2023-10-13 12:05:45,025 django.request ERROR    Internal Server Error: /api/v2/profiles/
2023-10-13 12:06:01,369 django.request WARNING  Unauthorized: /api/v2/profiles/
2023-10-13 12:06:07,491 django.request WARNING  Unauthorized: /api/v2/profiles/
2023-10-13 12:06:20,916 django.request WARNING  Unauthorized: /api/v2/profiles/
2023-10-13 12:06:52,383 django.request WARNING  Unauthorized: /api/v2/profiles/
2023-10-13 12:10:23,800 django.request WARNING  Unauthorized: /api/v2/profiles/
2023-10-13 12:11:12,678 django.request WARNING  Unauthorized: /api/v2/profiles/
2023-10-13 12:18:15,196 django.request WARNING  Unauthorized: /api/v2/profiles/
2023-10-13 12:18:37,274 django.request WARNING  Unauthorized: /api/v2/profiles/
2023-10-13 12:25:35,666 django.request WARNING  Unauthorized: /api/v2/profiles/
2023-10-13 12:33:22,217 django.request WARNING  Unauthorized: /api/v2/profiles/
2023-10-13 12:33:42,818 django.request WARNING  Unauthorized: /api/v2/profiles/
2023-10-13 12:41:15,869 django.request ERROR    Internal Server Error: /api/v2/profiles/
Traceback (most recent call last):
  File "/home/kayprogrammer/Documents/Projects/Django/socialnet-v2/env/lib/python3.11/site-packages/asgiref/sync.py", line 534, in thread_handler
    raise exc_info[1]
  File "/home/kayprogrammer/Documents/Projects/Django/socialnet-v2/env/lib/python3.11/site-packages/django/core/handlers/exception.py", line 42, in inner
    response = await get_response(request)
               ^^^^^^^^^^^^^^^^^^^^^^^^^^^
  File "/home/kayprogrammer/Documents/Projects/Django/socialnet-v2/env/lib/python3.11/site-packages/asgiref/sync.py", line 534, in thread_handler
    raise exc_info[1]
  File "/home/kayprogrammer/Documents/Projects/Django/socialnet-v2/env/lib/python3.11/site-packages/django/core/handlers/base.py", line 253, in _get_response_async
    response = await wrapped_callback(
               ^^^^^^^^^^^^^^^^^^^^^^^
  File "/home/kayprogrammer/Documents/Projects/Django/socialnet-v2/env/lib/python3.11/site-packages/ninja/operation.py", line 390, in _async_view
    return await cast(AsyncOperation, operation).run(request, *a, **kw)
           ^^^^^^^^^^^^^^^^^^^^^^^^^^^^^^^^^^^^^^^^^^^^^^^^^^^^^^^^^^^^
  File "/home/kayprogrammer/Documents/Projects/Django/socialnet-v2/env/lib/python3.11/site-packages/ninja/operation.py", line 259, in run
    error = await self._run_checks(request)
            ^^^^^^^^^^^^^^^^^^^^^^^^^^^^^^^
  File "/home/kayprogrammer/Documents/Projects/Django/socialnet-v2/env/lib/python3.11/site-packages/ninja/operation.py", line 274, in _run_checks
    error = await self._run_authentication(request)
            ^^^^^^^^^^^^^^^^^^^^^^^^^^^^^^^^^^^^^^^
  File "/home/kayprogrammer/Documents/Projects/Django/socialnet-v2/env/lib/python3.11/site-packages/ninja/operation.py", line 299, in _run_authentication
    return self.api.on_exception(request, AuthenticationError())
           ^^^^^^^^^^^^^^^^^^^^^^^^^^^^^^^^^^^^^^^^^^^^^^^^^^^^^
  File "/home/kayprogrammer/Documents/Projects/Django/socialnet-v2/env/lib/python3.11/site-packages/ninja/main.py", line 471, in on_exception
    return handler(request, exc)
           ^^^^^^^^^^^^^^^^^^^^^
  File "/home/kayprogrammer/Documents/Projects/Django/socialnet-v2/apps/api.py", line 48, in request_exc_handler
    print(vars(request.resolver_match.view_name))
          ^^^^^^^^^^^^^^^^^^^^^^^^^^^^^^^^^^^^^^
TypeError: vars() argument must have __dict__ attribute
2023-10-13 12:41:25,143 django.request WARNING  Unauthorized: /api/v2/profiles/
2023-10-13 12:41:33,434 django.request WARNING  Unauthorized: /api/v2/profiles/
2023-10-13 12:41:59,042 django.request WARNING  Unauthorized: /api/v2/profiles/
2023-10-13 12:42:52,460 django       ERROR    'ASGIRequest' object has no attribute 'auth'
Traceback (most recent call last):
  File "/home/kayprogrammer/Documents/Projects/Django/socialnet-v2/env/lib/python3.11/site-packages/ninja/operation.py", line 265, in run
    result = await self.view_func(request, **values)
             ^^^^^^^^^^^^^^^^^^^^^^^^^^^^^^^^^^^^^^^
  File "/home/kayprogrammer/Documents/Projects/Django/socialnet-v2/apps/profiles/views.py", line 62, in retrieve_users
    user = await request.auth
                 ^^^^^^^^^^^^
AttributeError: 'ASGIRequest' object has no attribute 'auth'
2023-10-13 12:42:52,543 django.request ERROR    Internal Server Error: /api/v2/profiles/
2023-10-13 12:43:12,896 django       ERROR    'ASGIRequest' object has no attribute 'auth'
Traceback (most recent call last):
  File "/home/kayprogrammer/Documents/Projects/Django/socialnet-v2/env/lib/python3.11/site-packages/ninja/operation.py", line 265, in run
    result = await self.view_func(request, **values)
             ^^^^^^^^^^^^^^^^^^^^^^^^^^^^^^^^^^^^^^^
  File "/home/kayprogrammer/Documents/Projects/Django/socialnet-v2/apps/profiles/views.py", line 62, in retrieve_users
    user = await request.auth
                 ^^^^^^^^^^^^
AttributeError: 'ASGIRequest' object has no attribute 'auth'
2023-10-13 12:43:12,987 django.request ERROR    Internal Server Error: /api/v2/profiles/
2023-10-13 12:43:28,847 django       ERROR    object NoneType can't be used in 'await' expression
Traceback (most recent call last):
  File "/home/kayprogrammer/Documents/Projects/Django/socialnet-v2/env/lib/python3.11/site-packages/ninja/operation.py", line 265, in run
    result = await self.view_func(request, **values)
             ^^^^^^^^^^^^^^^^^^^^^^^^^^^^^^^^^^^^^^^
  File "/home/kayprogrammer/Documents/Projects/Django/socialnet-v2/apps/profiles/views.py", line 62, in retrieve_users
    user = await request.auth
           ^^^^^^^^^^^^^^^^^^
TypeError: object NoneType can't be used in 'await' expression
2023-10-13 12:43:28,942 django.request ERROR    Internal Server Error: /api/v2/profiles/
2023-10-13 12:44:12,088 django       ERROR    object NoneType can't be used in 'await' expression
Traceback (most recent call last):
  File "/home/kayprogrammer/Documents/Projects/Django/socialnet-v2/env/lib/python3.11/site-packages/ninja/operation.py", line 265, in run
    result = await self.view_func(request, **values)
             ^^^^^^^^^^^^^^^^^^^^^^^^^^^^^^^^^^^^^^^
  File "/home/kayprogrammer/Documents/Projects/Django/socialnet-v2/apps/profiles/views.py", line 62, in retrieve_users
    user = await request.auth
           ^^^^^^^^^^^^^^^^^^
TypeError: object NoneType can't be used in 'await' expression
2023-10-13 12:44:12,188 django.request ERROR    Internal Server Error: /api/v2/profiles/
2023-10-13 12:46:13,510 django       ERROR    object NoneType can't be used in 'await' expression
Traceback (most recent call last):
  File "/home/kayprogrammer/Documents/Projects/Django/socialnet-v2/env/lib/python3.11/site-packages/ninja/operation.py", line 265, in run
    result = await self.view_func(request, **values)
             ^^^^^^^^^^^^^^^^^^^^^^^^^^^^^^^^^^^^^^^
  File "/home/kayprogrammer/Documents/Projects/Django/socialnet-v2/apps/profiles/views.py", line 62, in retrieve_users
    user = await request.auth
           ^^^^^^^^^^^^^^^^^^
TypeError: object NoneType can't be used in 'await' expression
2023-10-13 12:46:13,600 django.request ERROR    Internal Server Error: /api/v2/profiles/
2023-10-13 12:46:25,800 django       ERROR    list.count() takes exactly one argument (0 given)
Traceback (most recent call last):
  File "/home/kayprogrammer/Documents/Projects/Django/socialnet-v2/env/lib/python3.11/site-packages/ninja/operation.py", line 265, in run
    result = await self.view_func(request, **values)
             ^^^^^^^^^^^^^^^^^^^^^^^^^^^^^^^^^^^^^^^
  File "/home/kayprogrammer/Documents/Projects/Django/socialnet-v2/apps/profiles/views.py", line 64, in retrieve_users
    paginated_users = paginator.paginate_queryset(users)
                      ^^^^^^^^^^^^^^^^^^^^^^^^^^^^^^^^^^
  File "/home/kayprogrammer/Documents/Projects/Django/socialnet-v2/apps/common/paginators.py", line 18, in paginate_queryset
    "total": queryset.count(),
             ^^^^^^^^^^^^^^^^
TypeError: list.count() takes exactly one argument (0 given)
2023-10-13 12:46:25,904 django.request ERROR    Internal Server Error: /api/v2/profiles/
2023-10-13 12:49:59,930 django       ERROR    1 validation error for NinjaResponseSchema
response -> data
  value is not a valid list (type=type_error.list)
Traceback (most recent call last):
  File "/home/kayprogrammer/Documents/Projects/Django/socialnet-v2/env/lib/python3.11/site-packages/ninja/operation.py", line 266, in run
    return self._result_to_response(request, result, temporal_response)
           ^^^^^^^^^^^^^^^^^^^^^^^^^^^^^^^^^^^^^^^^^^^^^^^^^^^^^^^^^^^^
  File "/home/kayprogrammer/Documents/Projects/Django/socialnet-v2/env/lib/python3.11/site-packages/ninja/operation.py", line 202, in _result_to_response
    result = response_model.from_orm(resp_object).dict(
             ^^^^^^^^^^^^^^^^^^^^^^^^^^^^^^^^^^^^
  File "/home/kayprogrammer/Documents/Projects/Django/socialnet-v2/env/lib/python3.11/site-packages/ninja/schema.py", line 164, in from_orm
    return super().from_orm(obj)
           ^^^^^^^^^^^^^^^^^^^^^
  File "pydantic/main.py", line 579, in pydantic.main.BaseModel.from_orm
pydantic.error_wrappers.ValidationError: 1 validation error for NinjaResponseSchema
response -> data
  value is not a valid list (type=type_error.list)
2023-10-13 12:50:00,067 django.request ERROR    Internal Server Error: /api/v2/profiles/
2023-10-13 12:50:27,447 django       ERROR    1 validation error for NinjaResponseSchema
response -> data
  value is not a valid list (type=type_error.list)
Traceback (most recent call last):
  File "/home/kayprogrammer/Documents/Projects/Django/socialnet-v2/env/lib/python3.11/site-packages/ninja/operation.py", line 266, in run
    return self._result_to_response(request, result, temporal_response)
           ^^^^^^^^^^^^^^^^^^^^^^^^^^^^^^^^^^^^^^^^^^^^^^^^^^^^^^^^^^^^
  File "/home/kayprogrammer/Documents/Projects/Django/socialnet-v2/env/lib/python3.11/site-packages/ninja/operation.py", line 202, in _result_to_response
    result = response_model.from_orm(resp_object).dict(
             ^^^^^^^^^^^^^^^^^^^^^^^^^^^^^^^^^^^^
  File "/home/kayprogrammer/Documents/Projects/Django/socialnet-v2/env/lib/python3.11/site-packages/ninja/schema.py", line 164, in from_orm
    return super().from_orm(obj)
           ^^^^^^^^^^^^^^^^^^^^^
  File "pydantic/main.py", line 579, in pydantic.main.BaseModel.from_orm
pydantic.error_wrappers.ValidationError: 1 validation error for NinjaResponseSchema
response -> data
  value is not a valid list (type=type_error.list)
2023-10-13 12:50:27,554 django.request ERROR    Internal Server Error: /api/v2/profiles/
2023-10-13 12:50:46,186 django       ERROR    1 validation error for NinjaResponseSchema
response -> data
  value is not a valid list (type=type_error.list)
Traceback (most recent call last):
  File "/home/kayprogrammer/Documents/Projects/Django/socialnet-v2/env/lib/python3.11/site-packages/ninja/operation.py", line 266, in run
    return self._result_to_response(request, result, temporal_response)
           ^^^^^^^^^^^^^^^^^^^^^^^^^^^^^^^^^^^^^^^^^^^^^^^^^^^^^^^^^^^^
  File "/home/kayprogrammer/Documents/Projects/Django/socialnet-v2/env/lib/python3.11/site-packages/ninja/operation.py", line 202, in _result_to_response
    result = response_model.from_orm(resp_object).dict(
             ^^^^^^^^^^^^^^^^^^^^^^^^^^^^^^^^^^^^
  File "/home/kayprogrammer/Documents/Projects/Django/socialnet-v2/env/lib/python3.11/site-packages/ninja/schema.py", line 164, in from_orm
    return super().from_orm(obj)
           ^^^^^^^^^^^^^^^^^^^^^
  File "pydantic/main.py", line 579, in pydantic.main.BaseModel.from_orm
pydantic.error_wrappers.ValidationError: 1 validation error for NinjaResponseSchema
response -> data
  value is not a valid list (type=type_error.list)
2023-10-13 12:50:46,289 django.request ERROR    Internal Server Error: /api/v2/profiles/
2023-10-13 12:51:01,745 django       ERROR    1 validation error for NinjaResponseSchema
response -> data
  value is not a valid list (type=type_error.list)
Traceback (most recent call last):
  File "/home/kayprogrammer/Documents/Projects/Django/socialnet-v2/env/lib/python3.11/site-packages/ninja/operation.py", line 266, in run
    return self._result_to_response(request, result, temporal_response)
           ^^^^^^^^^^^^^^^^^^^^^^^^^^^^^^^^^^^^^^^^^^^^^^^^^^^^^^^^^^^^
  File "/home/kayprogrammer/Documents/Projects/Django/socialnet-v2/env/lib/python3.11/site-packages/ninja/operation.py", line 202, in _result_to_response
    result = response_model.from_orm(resp_object).dict(
             ^^^^^^^^^^^^^^^^^^^^^^^^^^^^^^^^^^^^
  File "/home/kayprogrammer/Documents/Projects/Django/socialnet-v2/env/lib/python3.11/site-packages/ninja/schema.py", line 164, in from_orm
    return super().from_orm(obj)
           ^^^^^^^^^^^^^^^^^^^^^
  File "pydantic/main.py", line 579, in pydantic.main.BaseModel.from_orm
pydantic.error_wrappers.ValidationError: 1 validation error for NinjaResponseSchema
response -> data
  value is not a valid list (type=type_error.list)
2023-10-13 12:51:01,861 django.request ERROR    Internal Server Error: /api/v2/profiles/
2023-10-13 12:51:19,138 django       ERROR    1 validation error for NinjaResponseSchema
response -> data
  value is not a valid list (type=type_error.list)
Traceback (most recent call last):
  File "/home/kayprogrammer/Documents/Projects/Django/socialnet-v2/env/lib/python3.11/site-packages/ninja/operation.py", line 266, in run
    return self._result_to_response(request, result, temporal_response)
           ^^^^^^^^^^^^^^^^^^^^^^^^^^^^^^^^^^^^^^^^^^^^^^^^^^^^^^^^^^^^
  File "/home/kayprogrammer/Documents/Projects/Django/socialnet-v2/env/lib/python3.11/site-packages/ninja/operation.py", line 202, in _result_to_response
    result = response_model.from_orm(resp_object).dict(
             ^^^^^^^^^^^^^^^^^^^^^^^^^^^^^^^^^^^^
  File "/home/kayprogrammer/Documents/Projects/Django/socialnet-v2/env/lib/python3.11/site-packages/ninja/schema.py", line 164, in from_orm
    return super().from_orm(obj)
           ^^^^^^^^^^^^^^^^^^^^^
  File "pydantic/main.py", line 579, in pydantic.main.BaseModel.from_orm
pydantic.error_wrappers.ValidationError: 1 validation error for NinjaResponseSchema
response -> data
  value is not a valid list (type=type_error.list)
2023-10-13 12:51:19,243 django.request ERROR    Internal Server Error: /api/v2/profiles/
2023-10-13 12:51:48,363 django       ERROR    1 validation error for NinjaResponseSchema
response -> data
  value is not a valid list (type=type_error.list)
Traceback (most recent call last):
  File "/home/kayprogrammer/Documents/Projects/Django/socialnet-v2/env/lib/python3.11/site-packages/ninja/operation.py", line 266, in run
    return self._result_to_response(request, result, temporal_response)
           ^^^^^^^^^^^^^^^^^^^^^^^^^^^^^^^^^^^^^^^^^^^^^^^^^^^^^^^^^^^^
  File "/home/kayprogrammer/Documents/Projects/Django/socialnet-v2/env/lib/python3.11/site-packages/ninja/operation.py", line 202, in _result_to_response
    result = response_model.from_orm(resp_object).dict(
             ^^^^^^^^^^^^^^^^^^^^^^^^^^^^^^^^^^^^
  File "/home/kayprogrammer/Documents/Projects/Django/socialnet-v2/env/lib/python3.11/site-packages/ninja/schema.py", line 164, in from_orm
    return super().from_orm(obj)
           ^^^^^^^^^^^^^^^^^^^^^
  File "pydantic/main.py", line 579, in pydantic.main.BaseModel.from_orm
pydantic.error_wrappers.ValidationError: 1 validation error for NinjaResponseSchema
response -> data
  value is not a valid list (type=type_error.list)
2023-10-13 12:51:48,467 django.request ERROR    Internal Server Error: /api/v2/profiles/
2023-10-13 12:59:13,010 django       ERROR    2 validation errors for NinjaResponseSchema
response -> data -> 0
  value is not a valid dict (type=type_error.dict)
response -> data -> 1
  value is not a valid dict (type=type_error.dict)
Traceback (most recent call last):
  File "/home/kayprogrammer/Documents/Projects/Django/socialnet-v2/env/lib/python3.11/site-packages/ninja/operation.py", line 266, in run
    return self._result_to_response(request, result, temporal_response)
           ^^^^^^^^^^^^^^^^^^^^^^^^^^^^^^^^^^^^^^^^^^^^^^^^^^^^^^^^^^^^
  File "/home/kayprogrammer/Documents/Projects/Django/socialnet-v2/env/lib/python3.11/site-packages/ninja/operation.py", line 202, in _result_to_response
    result = response_model.from_orm(resp_object).dict(
             ^^^^^^^^^^^^^^^^^^^^^^^^^^^^^^^^^^^^
  File "/home/kayprogrammer/Documents/Projects/Django/socialnet-v2/env/lib/python3.11/site-packages/ninja/schema.py", line 164, in from_orm
    return super().from_orm(obj)
           ^^^^^^^^^^^^^^^^^^^^^
  File "pydantic/main.py", line 579, in pydantic.main.BaseModel.from_orm
pydantic.error_wrappers.ValidationError: 2 validation errors for NinjaResponseSchema
response -> data -> 0
  value is not a valid dict (type=type_error.dict)
response -> data -> 1
  value is not a valid dict (type=type_error.dict)
2023-10-13 12:59:13,207 django.request ERROR    Internal Server Error: /api/v2/profiles/
2023-10-13 13:02:39,231 django       ERROR    2 validation errors for NinjaResponseSchema
response -> data -> 0
  value is not a valid dict (type=type_error.dict)
response -> data -> 1
  value is not a valid dict (type=type_error.dict)
Traceback (most recent call last):
  File "/home/kayprogrammer/Documents/Projects/Django/socialnet-v2/env/lib/python3.11/site-packages/ninja/operation.py", line 266, in run
    return self._result_to_response(request, result, temporal_response)
           ^^^^^^^^^^^^^^^^^^^^^^^^^^^^^^^^^^^^^^^^^^^^^^^^^^^^^^^^^^^^
  File "/home/kayprogrammer/Documents/Projects/Django/socialnet-v2/env/lib/python3.11/site-packages/ninja/operation.py", line 202, in _result_to_response
    result = response_model.from_orm(resp_object).dict(
             ^^^^^^^^^^^^^^^^^^^^^^^^^^^^^^^^^^^^
  File "/home/kayprogrammer/Documents/Projects/Django/socialnet-v2/env/lib/python3.11/site-packages/ninja/schema.py", line 164, in from_orm
    return super().from_orm(obj)
           ^^^^^^^^^^^^^^^^^^^^^
  File "pydantic/main.py", line 579, in pydantic.main.BaseModel.from_orm
pydantic.error_wrappers.ValidationError: 2 validation errors for NinjaResponseSchema
response -> data -> 0
  value is not a valid dict (type=type_error.dict)
response -> data -> 1
  value is not a valid dict (type=type_error.dict)
2023-10-13 13:02:39,341 django.request ERROR    Internal Server Error: /api/v2/profiles/
2023-10-13 13:02:58,862 django       ERROR    2 validation errors for NinjaResponseSchema
response -> data -> 0
  value is not a valid dict (type=type_error.dict)
response -> data -> 1
  value is not a valid dict (type=type_error.dict)
Traceback (most recent call last):
  File "/home/kayprogrammer/Documents/Projects/Django/socialnet-v2/env/lib/python3.11/site-packages/ninja/operation.py", line 266, in run
    return self._result_to_response(request, result, temporal_response)
           ^^^^^^^^^^^^^^^^^^^^^^^^^^^^^^^^^^^^^^^^^^^^^^^^^^^^^^^^^^^^
  File "/home/kayprogrammer/Documents/Projects/Django/socialnet-v2/env/lib/python3.11/site-packages/ninja/operation.py", line 202, in _result_to_response
    result = response_model.from_orm(resp_object).dict(
             ^^^^^^^^^^^^^^^^^^^^^^^^^^^^^^^^^^^^
  File "/home/kayprogrammer/Documents/Projects/Django/socialnet-v2/env/lib/python3.11/site-packages/ninja/schema.py", line 164, in from_orm
    return super().from_orm(obj)
           ^^^^^^^^^^^^^^^^^^^^^
  File "pydantic/main.py", line 579, in pydantic.main.BaseModel.from_orm
pydantic.error_wrappers.ValidationError: 2 validation errors for NinjaResponseSchema
response -> data -> 0
  value is not a valid dict (type=type_error.dict)
response -> data -> 1
  value is not a valid dict (type=type_error.dict)
2023-10-13 13:02:58,899 django.request ERROR    Internal Server Error: /api/v2/profiles/
2023-10-13 13:09:38,604 django       ERROR    2 validation errors for NinjaResponseSchema
response -> data -> 0
  value is not a valid dict (type=type_error.dict)
response -> data -> 1
  value is not a valid dict (type=type_error.dict)
Traceback (most recent call last):
  File "/home/kayprogrammer/Documents/Projects/Django/socialnet-v2/env/lib/python3.11/site-packages/ninja/operation.py", line 266, in run
    return self._result_to_response(request, result, temporal_response)
           ^^^^^^^^^^^^^^^^^^^^^^^^^^^^^^^^^^^^^^^^^^^^^^^^^^^^^^^^^^^^
  File "/home/kayprogrammer/Documents/Projects/Django/socialnet-v2/env/lib/python3.11/site-packages/ninja/operation.py", line 202, in _result_to_response
    result = response_model.from_orm(resp_object).dict(
             ^^^^^^^^^^^^^^^^^^^^^^^^^^^^^^^^^^^^
  File "/home/kayprogrammer/Documents/Projects/Django/socialnet-v2/env/lib/python3.11/site-packages/ninja/schema.py", line 164, in from_orm
    return super().from_orm(obj)
           ^^^^^^^^^^^^^^^^^^^^^
  File "pydantic/main.py", line 579, in pydantic.main.BaseModel.from_orm
pydantic.error_wrappers.ValidationError: 2 validation errors for NinjaResponseSchema
response -> data -> 0
  value is not a valid dict (type=type_error.dict)
response -> data -> 1
  value is not a valid dict (type=type_error.dict)
2023-10-13 13:09:38,655 django.request ERROR    Internal Server Error: /api/v2/profiles/
2023-10-13 13:09:41,664 django       ERROR    2 validation errors for NinjaResponseSchema
response -> data -> 0
  value is not a valid dict (type=type_error.dict)
response -> data -> 1
  value is not a valid dict (type=type_error.dict)
Traceback (most recent call last):
  File "/home/kayprogrammer/Documents/Projects/Django/socialnet-v2/env/lib/python3.11/site-packages/ninja/operation.py", line 266, in run
    return self._result_to_response(request, result, temporal_response)
           ^^^^^^^^^^^^^^^^^^^^^^^^^^^^^^^^^^^^^^^^^^^^^^^^^^^^^^^^^^^^
  File "/home/kayprogrammer/Documents/Projects/Django/socialnet-v2/env/lib/python3.11/site-packages/ninja/operation.py", line 202, in _result_to_response
    result = response_model.from_orm(resp_object).dict(
             ^^^^^^^^^^^^^^^^^^^^^^^^^^^^^^^^^^^^
  File "/home/kayprogrammer/Documents/Projects/Django/socialnet-v2/env/lib/python3.11/site-packages/ninja/schema.py", line 164, in from_orm
    return super().from_orm(obj)
           ^^^^^^^^^^^^^^^^^^^^^
  File "pydantic/main.py", line 579, in pydantic.main.BaseModel.from_orm
pydantic.error_wrappers.ValidationError: 2 validation errors for NinjaResponseSchema
response -> data -> 0
  value is not a valid dict (type=type_error.dict)
response -> data -> 1
  value is not a valid dict (type=type_error.dict)
2023-10-13 13:09:41,715 django.request ERROR    Internal Server Error: /api/v2/profiles/
2023-10-13 13:11:53,923 django       ERROR    12 validation errors for NinjaResponseSchema
response -> data -> 0 -> avatar
  none is not an allowed value (type=type_error.none.not_allowed)
response -> data -> 0 -> bio
  none is not an allowed value (type=type_error.none.not_allowed)
response -> data -> 0 -> dob
  none is not an allowed value (type=type_error.none.not_allowed)
response -> data -> 0 -> city
  none is not an allowed value (type=type_error.none.not_allowed)
response -> data -> 0 -> city_id
  none is not an allowed value (type=type_error.none.not_allowed)
response -> data -> 0 -> file_type
  field required (type=value_error.missing)
response -> data -> 1 -> avatar
  none is not an allowed value (type=type_error.none.not_allowed)
response -> data -> 1 -> bio
  none is not an allowed value (type=type_error.none.not_allowed)
response -> data -> 1 -> dob
  none is not an allowed value (type=type_error.none.not_allowed)
response -> data -> 1 -> city
  none is not an allowed value (type=type_error.none.not_allowed)
response -> data -> 1 -> city_id
  none is not an allowed value (type=type_error.none.not_allowed)
response -> data -> 1 -> file_type
  field required (type=value_error.missing)
Traceback (most recent call last):
  File "/home/kayprogrammer/Documents/Projects/Django/socialnet-v2/env/lib/python3.11/site-packages/ninja/operation.py", line 266, in run
    return self._result_to_response(request, result, temporal_response)
           ^^^^^^^^^^^^^^^^^^^^^^^^^^^^^^^^^^^^^^^^^^^^^^^^^^^^^^^^^^^^
  File "/home/kayprogrammer/Documents/Projects/Django/socialnet-v2/env/lib/python3.11/site-packages/ninja/operation.py", line 202, in _result_to_response
    result = response_model.from_orm(resp_object).dict(
             ^^^^^^^^^^^^^^^^^^^^^^^^^^^^^^^^^^^^
  File "/home/kayprogrammer/Documents/Projects/Django/socialnet-v2/env/lib/python3.11/site-packages/ninja/schema.py", line 164, in from_orm
    return super().from_orm(obj)
           ^^^^^^^^^^^^^^^^^^^^^
  File "pydantic/main.py", line 579, in pydantic.main.BaseModel.from_orm
pydantic.error_wrappers.ValidationError: 12 validation errors for NinjaResponseSchema
response -> data -> 0 -> avatar
  none is not an allowed value (type=type_error.none.not_allowed)
response -> data -> 0 -> bio
  none is not an allowed value (type=type_error.none.not_allowed)
response -> data -> 0 -> dob
  none is not an allowed value (type=type_error.none.not_allowed)
response -> data -> 0 -> city
  none is not an allowed value (type=type_error.none.not_allowed)
response -> data -> 0 -> city_id
  none is not an allowed value (type=type_error.none.not_allowed)
response -> data -> 0 -> file_type
  field required (type=value_error.missing)
response -> data -> 1 -> avatar
  none is not an allowed value (type=type_error.none.not_allowed)
response -> data -> 1 -> bio
  none is not an allowed value (type=type_error.none.not_allowed)
response -> data -> 1 -> dob
  none is not an allowed value (type=type_error.none.not_allowed)
response -> data -> 1 -> city
  none is not an allowed value (type=type_error.none.not_allowed)
response -> data -> 1 -> city_id
  none is not an allowed value (type=type_error.none.not_allowed)
response -> data -> 1 -> file_type
  field required (type=value_error.missing)
2023-10-13 13:11:54,032 django.request ERROR    Internal Server Error: /api/v2/profiles/
2023-10-13 13:13:16,813 django       ERROR    4 validation errors for NinjaResponseSchema
response -> data -> 0 -> city_id
  none is not an allowed value (type=type_error.none.not_allowed)
response -> data -> 0 -> file_type
  field required (type=value_error.missing)
response -> data -> 1 -> city_id
  none is not an allowed value (type=type_error.none.not_allowed)
response -> data -> 1 -> file_type
  field required (type=value_error.missing)
Traceback (most recent call last):
  File "/home/kayprogrammer/Documents/Projects/Django/socialnet-v2/env/lib/python3.11/site-packages/ninja/operation.py", line 266, in run
    return self._result_to_response(request, result, temporal_response)
           ^^^^^^^^^^^^^^^^^^^^^^^^^^^^^^^^^^^^^^^^^^^^^^^^^^^^^^^^^^^^
  File "/home/kayprogrammer/Documents/Projects/Django/socialnet-v2/env/lib/python3.11/site-packages/ninja/operation.py", line 202, in _result_to_response
    result = response_model.from_orm(resp_object).dict(
             ^^^^^^^^^^^^^^^^^^^^^^^^^^^^^^^^^^^^
  File "/home/kayprogrammer/Documents/Projects/Django/socialnet-v2/env/lib/python3.11/site-packages/ninja/schema.py", line 164, in from_orm
    return super().from_orm(obj)
           ^^^^^^^^^^^^^^^^^^^^^
  File "pydantic/main.py", line 579, in pydantic.main.BaseModel.from_orm
pydantic.error_wrappers.ValidationError: 4 validation errors for NinjaResponseSchema
response -> data -> 0 -> city_id
  none is not an allowed value (type=type_error.none.not_allowed)
response -> data -> 0 -> file_type
  field required (type=value_error.missing)
response -> data -> 1 -> city_id
  none is not an allowed value (type=type_error.none.not_allowed)
response -> data -> 1 -> file_type
  field required (type=value_error.missing)
2023-10-13 13:13:16,916 django.request ERROR    Internal Server Error: /api/v2/profiles/
2023-10-13 13:13:35,434 django       ERROR    2 validation errors for NinjaResponseSchema
response -> data -> 0 -> file_type
  field required (type=value_error.missing)
response -> data -> 1 -> file_type
  field required (type=value_error.missing)
Traceback (most recent call last):
  File "/home/kayprogrammer/Documents/Projects/Django/socialnet-v2/env/lib/python3.11/site-packages/ninja/operation.py", line 266, in run
    return self._result_to_response(request, result, temporal_response)
           ^^^^^^^^^^^^^^^^^^^^^^^^^^^^^^^^^^^^^^^^^^^^^^^^^^^^^^^^^^^^
  File "/home/kayprogrammer/Documents/Projects/Django/socialnet-v2/env/lib/python3.11/site-packages/ninja/operation.py", line 202, in _result_to_response
    result = response_model.from_orm(resp_object).dict(
             ^^^^^^^^^^^^^^^^^^^^^^^^^^^^^^^^^^^^
  File "/home/kayprogrammer/Documents/Projects/Django/socialnet-v2/env/lib/python3.11/site-packages/ninja/schema.py", line 164, in from_orm
    return super().from_orm(obj)
           ^^^^^^^^^^^^^^^^^^^^^
  File "pydantic/main.py", line 579, in pydantic.main.BaseModel.from_orm
pydantic.error_wrappers.ValidationError: 2 validation errors for NinjaResponseSchema
response -> data -> 0 -> file_type
  field required (type=value_error.missing)
response -> data -> 1 -> file_type
  field required (type=value_error.missing)
2023-10-13 13:13:35,537 django.request ERROR    Internal Server Error: /api/v2/profiles/
2023-10-13 13:47:15,819 django.request WARNING  Not Found: /static/media/banner2-icon3.png
2023-10-13 13:47:16,634 django.request WARNING  Not Found: /static/media/logo.png
2023-10-13 13:47:21,019 jazzmin.utils WARNING  listings not found when generating links
2023-10-13 13:47:21,022 jazzmin.templatetags.jazzmin WARNING  avatar field must be an ImageField/URLField on the user model, or a callable
2023-10-13 13:47:21,720 django.request WARNING  Not Found: /static/media/banner2-icon3.png
2023-10-13 13:47:24,277 jazzmin.utils WARNING  listings not found when generating links
2023-10-13 13:47:24,281 jazzmin.templatetags.jazzmin WARNING  avatar field must be an ImageField/URLField on the user model, or a callable
2023-10-13 13:47:25,250 django.request WARNING  Not Found: /static/media/banner2-icon3.png
2023-10-13 13:48:50,211 jazzmin.utils WARNING  listings not found when generating links
2023-10-13 13:48:50,214 jazzmin.templatetags.jazzmin WARNING  avatar field must be an ImageField/URLField on the user model, or a callable
2023-10-13 13:48:51,434 django.request WARNING  Not Found: /static/media/banner2-icon3.png
2023-10-13 14:04:10,735 django.request WARNING  Not Found: /api/v2/profiles/
2023-10-13 14:04:12,737 django.request WARNING  Not Found: /api/v2/profiles/
2023-10-13 14:12:34,257 django.request WARNING  Bad Request: /api/v2/profiles/
2023-10-13 14:12:36,332 django.request WARNING  Bad Request: /api/v2/profiles/
2023-10-13 14:30:21,656 django       ERROR    1 validation error for NinjaResponseSchema
response -> data -> users
  field required (type=value_error.missing)
Traceback (most recent call last):
  File "/home/kayprogrammer/Documents/Projects/Django/socialnet-v2/env/lib/python3.11/site-packages/ninja/operation.py", line 266, in run
    return self._result_to_response(request, result, temporal_response)
           ^^^^^^^^^^^^^^^^^^^^^^^^^^^^^^^^^^^^^^^^^^^^^^^^^^^^^^^^^^^^
  File "/home/kayprogrammer/Documents/Projects/Django/socialnet-v2/env/lib/python3.11/site-packages/ninja/operation.py", line 202, in _result_to_response
    result = response_model.from_orm(resp_object).dict(
             ^^^^^^^^^^^^^^^^^^^^^^^^^^^^^^^^^^^^
  File "/home/kayprogrammer/Documents/Projects/Django/socialnet-v2/env/lib/python3.11/site-packages/ninja/schema.py", line 164, in from_orm
    return super().from_orm(obj)
           ^^^^^^^^^^^^^^^^^^^^^
  File "pydantic/main.py", line 579, in pydantic.main.BaseModel.from_orm
pydantic.error_wrappers.ValidationError: 1 validation error for NinjaResponseSchema
response -> data -> users
  field required (type=value_error.missing)
2023-10-13 14:30:21,760 django.request ERROR    Internal Server Error: /api/v2/profiles/
2023-10-13 14:32:26,295 django       ERROR    1 validation error for NinjaResponseSchema
response -> data -> users
  field required (type=value_error.missing)
Traceback (most recent call last):
  File "/home/kayprogrammer/Documents/Projects/Django/socialnet-v2/env/lib/python3.11/site-packages/ninja/operation.py", line 266, in run
    return self._result_to_response(request, result, temporal_response)
           ^^^^^^^^^^^^^^^^^^^^^^^^^^^^^^^^^^^^^^^^^^^^^^^^^^^^^^^^^^^^
  File "/home/kayprogrammer/Documents/Projects/Django/socialnet-v2/env/lib/python3.11/site-packages/ninja/operation.py", line 202, in _result_to_response
    result = response_model.from_orm(resp_object).dict(
             ^^^^^^^^^^^^^^^^^^^^^^^^^^^^^^^^^^^^
  File "/home/kayprogrammer/Documents/Projects/Django/socialnet-v2/env/lib/python3.11/site-packages/ninja/schema.py", line 164, in from_orm
    return super().from_orm(obj)
           ^^^^^^^^^^^^^^^^^^^^^
  File "pydantic/main.py", line 579, in pydantic.main.BaseModel.from_orm
pydantic.error_wrappers.ValidationError: 1 validation error for NinjaResponseSchema
response -> data -> users
  field required (type=value_error.missing)
2023-10-13 14:32:26,399 django.request ERROR    Internal Server Error: /api/v2/profiles/
2023-10-13 14:32:41,149 django       ERROR    1 validation error for NinjaResponseSchema
response -> data -> users
  field required (type=value_error.missing)
Traceback (most recent call last):
  File "/home/kayprogrammer/Documents/Projects/Django/socialnet-v2/env/lib/python3.11/site-packages/ninja/operation.py", line 266, in run
    return self._result_to_response(request, result, temporal_response)
           ^^^^^^^^^^^^^^^^^^^^^^^^^^^^^^^^^^^^^^^^^^^^^^^^^^^^^^^^^^^^
  File "/home/kayprogrammer/Documents/Projects/Django/socialnet-v2/env/lib/python3.11/site-packages/ninja/operation.py", line 202, in _result_to_response
    result = response_model.from_orm(resp_object).dict(
             ^^^^^^^^^^^^^^^^^^^^^^^^^^^^^^^^^^^^
  File "/home/kayprogrammer/Documents/Projects/Django/socialnet-v2/env/lib/python3.11/site-packages/ninja/schema.py", line 164, in from_orm
    return super().from_orm(obj)
           ^^^^^^^^^^^^^^^^^^^^^
  File "pydantic/main.py", line 579, in pydantic.main.BaseModel.from_orm
pydantic.error_wrappers.ValidationError: 1 validation error for NinjaResponseSchema
response -> data -> users
  field required (type=value_error.missing)
2023-10-13 14:32:41,196 django.request ERROR    Internal Server Error: /api/v2/profiles/
2023-10-13 14:35:04,293 django       ERROR    1 validation error for NinjaResponseSchema
response -> data -> users
  field required (type=value_error.missing)
Traceback (most recent call last):
  File "/home/kayprogrammer/Documents/Projects/Django/socialnet-v2/env/lib/python3.11/site-packages/ninja/operation.py", line 266, in run
    return self._result_to_response(request, result, temporal_response)
           ^^^^^^^^^^^^^^^^^^^^^^^^^^^^^^^^^^^^^^^^^^^^^^^^^^^^^^^^^^^^
  File "/home/kayprogrammer/Documents/Projects/Django/socialnet-v2/env/lib/python3.11/site-packages/ninja/operation.py", line 202, in _result_to_response
    result = response_model.from_orm(resp_object).dict(
             ^^^^^^^^^^^^^^^^^^^^^^^^^^^^^^^^^^^^
  File "/home/kayprogrammer/Documents/Projects/Django/socialnet-v2/env/lib/python3.11/site-packages/ninja/schema.py", line 164, in from_orm
    return super().from_orm(obj)
           ^^^^^^^^^^^^^^^^^^^^^
  File "pydantic/main.py", line 579, in pydantic.main.BaseModel.from_orm
pydantic.error_wrappers.ValidationError: 1 validation error for NinjaResponseSchema
response -> data -> users
  field required (type=value_error.missing)
2023-10-13 14:35:04,433 django.request ERROR    Internal Server Error: /api/v2/profiles/
2023-10-13 14:35:56,332 django       ERROR    1 validation error for NinjaResponseSchema
response -> data -> users
  field required (type=value_error.missing)
Traceback (most recent call last):
  File "/home/kayprogrammer/Documents/Projects/Django/socialnet-v2/env/lib/python3.11/site-packages/ninja/operation.py", line 266, in run
    return self._result_to_response(request, result, temporal_response)
           ^^^^^^^^^^^^^^^^^^^^^^^^^^^^^^^^^^^^^^^^^^^^^^^^^^^^^^^^^^^^
  File "/home/kayprogrammer/Documents/Projects/Django/socialnet-v2/env/lib/python3.11/site-packages/ninja/operation.py", line 202, in _result_to_response
    result = response_model.from_orm(resp_object).dict(
             ^^^^^^^^^^^^^^^^^^^^^^^^^^^^^^^^^^^^
  File "/home/kayprogrammer/Documents/Projects/Django/socialnet-v2/env/lib/python3.11/site-packages/ninja/schema.py", line 164, in from_orm
    return super().from_orm(obj)
           ^^^^^^^^^^^^^^^^^^^^^
  File "pydantic/main.py", line 579, in pydantic.main.BaseModel.from_orm
pydantic.error_wrappers.ValidationError: 1 validation error for NinjaResponseSchema
response -> data -> users
  field required (type=value_error.missing)
2023-10-13 14:35:56,449 django.request ERROR    Internal Server Error: /api/v2/profiles/
2023-10-13 14:36:21,157 django.request WARNING  Bad Request: /api/v2/profiles/
2023-10-13 14:36:33,693 django.request WARNING  Bad Request: /api/v2/profiles/
2023-10-13 14:36:47,381 django.request WARNING  Bad Request: /api/v2/profiles/
2023-10-13 14:36:53,796 django.request WARNING  Bad Request: /api/v2/profiles/
2023-10-13 14:37:24,159 django.request WARNING  Not Found: /favicon.ico
2023-10-13 14:38:35,395 django.request WARNING  Bad Request: /api/v2/profiles/
2023-10-13 14:41:08,873 django       ERROR    'coroutine' object has no attribute 'id'
Traceback (most recent call last):
  File "/home/kayprogrammer/Documents/Projects/Django/socialnet-v2/env/lib/python3.11/site-packages/ninja/operation.py", line 265, in run
    result = await self.view_func(request, **values)
             ^^^^^^^^^^^^^^^^^^^^^^^^^^^^^^^^^^^^^^^
  File "/home/kayprogrammer/Documents/Projects/Django/socialnet-v2/apps/profiles/views.py", line 61, in retrieve_users
    users = get_users_queryset(user)
            ^^^^^^^^^^^^^^^^^^^^^^^^
  File "/home/kayprogrammer/Documents/Projects/Django/socialnet-v2/apps/profiles/views.py", line 19, in get_users_queryset
    users = users.exclude(id=current_user.id)
                             ^^^^^^^^^^^^^^^
AttributeError: 'coroutine' object has no attribute 'id'
2023-10-13 14:41:08,920 django.request ERROR    Internal Server Error: /api/v2/profiles/
2023-10-13 14:43:39,044 django       ERROR    'coroutine' object has no attribute 'id'
Traceback (most recent call last):
  File "/home/kayprogrammer/Documents/Projects/Django/socialnet-v2/env/lib/python3.11/site-packages/ninja/operation.py", line 265, in run
    result = await self.view_func(request, **values)
             ^^^^^^^^^^^^^^^^^^^^^^^^^^^^^^^^^^^^^^^
  File "/home/kayprogrammer/Documents/Projects/Django/socialnet-v2/apps/profiles/views.py", line 61, in retrieve_users
    users = get_users_queryset(user)
            ^^^^^^^^^^^^^^^^^^^^^^^^
  File "/home/kayprogrammer/Documents/Projects/Django/socialnet-v2/apps/profiles/views.py", line 19, in get_users_queryset
    users = users.exclude(id=current_user.id)
                             ^^^^^^^^^^^^^^^
AttributeError: 'coroutine' object has no attribute 'id'
2023-10-13 14:43:39,144 django.request ERROR    Internal Server Error: /api/v2/profiles/
2023-10-13 14:43:47,680 django.request WARNING  Bad Request: /api/v2/profiles/
2023-10-13 14:43:49,058 django.request WARNING  Bad Request: /api/v2/profiles/
2023-10-13 14:44:21,824 django.request ERROR    Internal Server Error: /api/v2/profiles/
Traceback (most recent call last):
  File "/home/kayprogrammer/Documents/Projects/Django/socialnet-v2/env/lib/python3.11/site-packages/asgiref/sync.py", line 534, in thread_handler
    raise exc_info[1]
  File "/home/kayprogrammer/Documents/Projects/Django/socialnet-v2/env/lib/python3.11/site-packages/django/core/handlers/exception.py", line 42, in inner
    response = await get_response(request)
               ^^^^^^^^^^^^^^^^^^^^^^^^^^^
  File "/home/kayprogrammer/Documents/Projects/Django/socialnet-v2/env/lib/python3.11/site-packages/django/core/handlers/base.py", line 265, in _get_response_async
    self.check_response(response, callback)
  File "/home/kayprogrammer/Documents/Projects/Django/socialnet-v2/env/lib/python3.11/site-packages/django/core/handlers/base.py", line 337, in check_response
    raise ValueError(
ValueError: The view ninja.operation.method.__call__ didn't return an HttpResponse object. It returned an unawaited coroutine instead. You may need to add an 'await' into your view.
2023-10-13 14:54:37,381 django       ERROR    6 validation errors for NinjaResponseSchema
response -> data -> 0 -> region
  str type expected (type=type_error.str)
response -> data -> 0 -> country
  str type expected (type=type_error.str)
response -> data -> 1 -> region
  str type expected (type=type_error.str)
response -> data -> 1 -> country
  str type expected (type=type_error.str)
response -> data -> 2 -> region
  str type expected (type=type_error.str)
response -> data -> 2 -> country
  str type expected (type=type_error.str)
Traceback (most recent call last):
  File "/home/kayprogrammer/Documents/Projects/Django/socialnet-v2/env/lib/python3.11/site-packages/ninja/operation.py", line 266, in run
    return self._result_to_response(request, result, temporal_response)
           ^^^^^^^^^^^^^^^^^^^^^^^^^^^^^^^^^^^^^^^^^^^^^^^^^^^^^^^^^^^^
  File "/home/kayprogrammer/Documents/Projects/Django/socialnet-v2/env/lib/python3.11/site-packages/ninja/operation.py", line 202, in _result_to_response
    result = response_model.from_orm(resp_object).dict(
             ^^^^^^^^^^^^^^^^^^^^^^^^^^^^^^^^^^^^
  File "/home/kayprogrammer/Documents/Projects/Django/socialnet-v2/env/lib/python3.11/site-packages/ninja/schema.py", line 164, in from_orm
    return super().from_orm(obj)
           ^^^^^^^^^^^^^^^^^^^^^
  File "pydantic/main.py", line 579, in pydantic.main.BaseModel.from_orm
pydantic.error_wrappers.ValidationError: 6 validation errors for NinjaResponseSchema
response -> data -> 0 -> region
  str type expected (type=type_error.str)
response -> data -> 0 -> country
  str type expected (type=type_error.str)
response -> data -> 1 -> region
  str type expected (type=type_error.str)
response -> data -> 1 -> country
  str type expected (type=type_error.str)
response -> data -> 2 -> region
  str type expected (type=type_error.str)
response -> data -> 2 -> country
  str type expected (type=type_error.str)
2023-10-13 14:54:37,432 django.request ERROR    Internal Server Error: /api/v2/profiles/cities/
2023-10-13 14:54:56,067 django       ERROR    6 validation errors for NinjaResponseSchema
response -> data -> 0 -> region
  str type expected (type=type_error.str)
response -> data -> 0 -> country
  str type expected (type=type_error.str)
response -> data -> 1 -> region
  str type expected (type=type_error.str)
response -> data -> 1 -> country
  str type expected (type=type_error.str)
response -> data -> 2 -> region
  str type expected (type=type_error.str)
response -> data -> 2 -> country
  str type expected (type=type_error.str)
Traceback (most recent call last):
  File "/home/kayprogrammer/Documents/Projects/Django/socialnet-v2/env/lib/python3.11/site-packages/ninja/operation.py", line 266, in run
    return self._result_to_response(request, result, temporal_response)
           ^^^^^^^^^^^^^^^^^^^^^^^^^^^^^^^^^^^^^^^^^^^^^^^^^^^^^^^^^^^^
  File "/home/kayprogrammer/Documents/Projects/Django/socialnet-v2/env/lib/python3.11/site-packages/ninja/operation.py", line 202, in _result_to_response
    result = response_model.from_orm(resp_object).dict(
             ^^^^^^^^^^^^^^^^^^^^^^^^^^^^^^^^^^^^
  File "/home/kayprogrammer/Documents/Projects/Django/socialnet-v2/env/lib/python3.11/site-packages/ninja/schema.py", line 164, in from_orm
    return super().from_orm(obj)
           ^^^^^^^^^^^^^^^^^^^^^
  File "pydantic/main.py", line 579, in pydantic.main.BaseModel.from_orm
pydantic.error_wrappers.ValidationError: 6 validation errors for NinjaResponseSchema
response -> data -> 0 -> region
  str type expected (type=type_error.str)
response -> data -> 0 -> country
  str type expected (type=type_error.str)
response -> data -> 1 -> region
  str type expected (type=type_error.str)
response -> data -> 1 -> country
  str type expected (type=type_error.str)
response -> data -> 2 -> region
  str type expected (type=type_error.str)
response -> data -> 2 -> country
  str type expected (type=type_error.str)
2023-10-13 14:54:56,249 django.request ERROR    Internal Server Error: /api/v2/profiles/cities/
2023-10-13 17:44:02,247 jazzmin.utils WARNING  listings not found when generating links
2023-10-13 17:44:02,283 jazzmin.templatetags.jazzmin WARNING  avatar field must be an ImageField/URLField on the user model, or a callable
2023-10-13 17:44:03,783 django.request WARNING  Not Found: /static/media/banner2-icon3.png
2023-10-13 17:44:04,700 django.request WARNING  Not Found: /static/media/logo.png
2023-10-13 17:46:25,556 django       ERROR    6 validation errors for NinjaResponseSchema
response -> data -> 0 -> region__name
  field required (type=value_error.missing)
response -> data -> 0 -> country__name
  field required (type=value_error.missing)
response -> data -> 1 -> region__name
  field required (type=value_error.missing)
response -> data -> 1 -> country__name
  field required (type=value_error.missing)
response -> data -> 2 -> region__name
  field required (type=value_error.missing)
response -> data -> 2 -> country__name
  field required (type=value_error.missing)
Traceback (most recent call last):
  File "/home/kayprogrammer/Documents/Projects/Django/socialnet-v2/env/lib/python3.11/site-packages/ninja/operation.py", line 266, in run
    return self._result_to_response(request, result, temporal_response)
           ^^^^^^^^^^^^^^^^^^^^^^^^^^^^^^^^^^^^^^^^^^^^^^^^^^^^^^^^^^^^
  File "/home/kayprogrammer/Documents/Projects/Django/socialnet-v2/env/lib/python3.11/site-packages/ninja/operation.py", line 202, in _result_to_response
    result = response_model.from_orm(resp_object).dict(
             ^^^^^^^^^^^^^^^^^^^^^^^^^^^^^^^^^^^^
  File "/home/kayprogrammer/Documents/Projects/Django/socialnet-v2/env/lib/python3.11/site-packages/ninja/schema.py", line 164, in from_orm
    return super().from_orm(obj)
           ^^^^^^^^^^^^^^^^^^^^^
  File "pydantic/main.py", line 579, in pydantic.main.BaseModel.from_orm
pydantic.error_wrappers.ValidationError: 6 validation errors for NinjaResponseSchema
response -> data -> 0 -> region__name
  field required (type=value_error.missing)
response -> data -> 0 -> country__name
  field required (type=value_error.missing)
response -> data -> 1 -> region__name
  field required (type=value_error.missing)
response -> data -> 1 -> country__name
  field required (type=value_error.missing)
response -> data -> 2 -> region__name
  field required (type=value_error.missing)
response -> data -> 2 -> country__name
  field required (type=value_error.missing)
2023-10-13 17:46:25,716 django.request ERROR    Internal Server Error: /api/v2/profiles/cities/
2023-10-13 17:54:44,594 django.request ERROR    Internal Server Error: /api/v2/profiles/cities/
Traceback (most recent call last):
  File "/home/kayprogrammer/Documents/Projects/Django/socialnet-v2/env/lib/python3.11/site-packages/django/core/handlers/exception.py", line 55, in inner
    response = get_response(request)
               ^^^^^^^^^^^^^^^^^^^^^
  File "/home/kayprogrammer/Documents/Projects/Django/socialnet-v2/env/lib/python3.11/site-packages/debug_toolbar/middleware.py", line 69, in __call__
    panel.generate_stats(request, response)
  File "/home/kayprogrammer/Documents/Projects/Django/socialnet-v2/apps/common/debug_toolbar_panel.py", line 7, in generate_stats
    sql_queries = self.get_stats(request)
                  ^^^^^^^^^^^^^^^^^^^^^^^
  File "/home/kayprogrammer/Documents/Projects/Django/socialnet-v2/apps/common/debug_toolbar_panel.py", line 24, in get_stats
    for query in self.get_collected_queries():
                 ^^^^^^^^^^^^^^^^^^^^^^^^^^
AttributeError: 'CustomSQLPanel' object has no attribute 'get_collected_queries'
